[2025-06-15T08:49:25.820+0000] {local_task_job_runner.py:120} INFO - ::group::Pre task execution logs
[2025-06-15T08:49:25.855+0000] {taskinstance.py:2076} INFO - Dependencies all met for dep_context=non-requeueable deps ti=<TaskInstance: globalsuperstore.extract.extract_and_load_to_staging scheduled__2025-02-17T00:00:00+00:00 [queued]>
[2025-06-15T08:49:25.866+0000] {taskinstance.py:2076} INFO - Dependencies all met for dep_context=requeueable deps ti=<TaskInstance: globalsuperstore.extract.extract_and_load_to_staging scheduled__2025-02-17T00:00:00+00:00 [queued]>
[2025-06-15T08:49:25.868+0000] {taskinstance.py:2306} INFO - Starting attempt 1 of 1
[2025-06-15T08:49:25.882+0000] {taskinstance.py:2330} INFO - Executing <Task(PythonOperator): extract.extract_and_load_to_staging> on 2025-02-17 00:00:00+00:00
[2025-06-15T08:49:25.888+0000] {standard_task_runner.py:63} INFO - Started process 1750 to run task
[2025-06-15T08:49:25.891+0000] {standard_task_runner.py:90} INFO - Running: ['***', 'tasks', 'run', 'globalsuperstore', 'extract.extract_and_load_to_staging', 'scheduled__2025-02-17T00:00:00+00:00', '--job-id', '259', '--raw', '--subdir', 'DAGS_FOLDER/global_superstore_dw_etl.py', '--cfg-path', '/tmp/tmpwlqi64o3']
[2025-06-15T08:49:25.893+0000] {standard_task_runner.py:91} INFO - Job 259: Subtask extract.extract_and_load_to_staging
[2025-06-15T08:49:25.934+0000] {task_command.py:426} INFO - Running <TaskInstance: globalsuperstore.extract.extract_and_load_to_staging scheduled__2025-02-17T00:00:00+00:00 [running]> on host f3cca4675eb8
[2025-06-15T08:49:26.032+0000] {taskinstance.py:2648} INFO - Exporting env vars: AIRFLOW_CTX_DAG_OWNER='***' AIRFLOW_CTX_DAG_ID='globalsuperstore' AIRFLOW_CTX_TASK_ID='extract.extract_and_load_to_staging' AIRFLOW_CTX_EXECUTION_DATE='2025-02-17T00:00:00+00:00' AIRFLOW_CTX_TRY_NUMBER='1' AIRFLOW_CTX_DAG_RUN_ID='scheduled__2025-02-17T00:00:00+00:00'
[2025-06-15T08:49:26.033+0000] {taskinstance.py:430} INFO - ::endgroup::
[2025-06-15T08:49:26.052+0000] {base.py:84} INFO - Using connection ID 'postgres' for task execution.
[2025-06-15T08:49:26.058+0000] {base.py:84} INFO - Using connection ID 'mysql' for task execution.
[2025-06-15T08:49:29.907+0000] {taskinstance.py:441} INFO - ::group::Post task execution logs
[2025-06-15T08:49:29.908+0000] {taskinstance.py:2905} ERROR - Task failed with exception
Traceback (most recent call last):
  File "/home/airflow/.local/lib/python3.10/site-packages/airflow/models/taskinstance.py", line 465, in _execute_task
    result = _execute_callable(context=context, **execute_callable_kwargs)
  File "/home/airflow/.local/lib/python3.10/site-packages/airflow/models/taskinstance.py", line 432, in _execute_callable
    return execute_callable(context=context, **execute_callable_kwargs)
  File "/home/airflow/.local/lib/python3.10/site-packages/airflow/models/baseoperator.py", line 401, in wrapper
    return func(self, *args, **kwargs)
  File "/home/airflow/.local/lib/python3.10/site-packages/airflow/operators/python.py", line 235, in execute
    return_value = self.execute_callable()
  File "/home/airflow/.local/lib/python3.10/site-packages/airflow/operators/python.py", line 252, in execute_callable
    return self.python_callable(*self.op_args, **self.op_kwargs)
  File "/opt/airflow/dags/extract_data.py", line 25, in extract_and_load_to_staging
    df = source_operator.get_data_to_pd(f"SELECT * FROM {table}")
  File "/opt/airflow/plugins/mysql_operator.py", line 15, in get_data_to_pd
    return self.mysqlhook.get_pandas_df(query)
  File "/home/airflow/.local/lib/python3.10/site-packages/airflow/providers/common/sql/hooks/sql.py", line 262, in get_pandas_df
    with closing(self.get_conn()) as conn:
  File "/home/airflow/.local/lib/python3.10/site-packages/airflow/providers/mysql/hooks/mysql.py", line 196, in get_conn
    return MySQLdb.connect(**conn_config)
  File "/home/airflow/.local/lib/python3.10/site-packages/MySQLdb/__init__.py", line 121, in Connect
    return Connection(*args, **kwargs)
  File "/home/airflow/.local/lib/python3.10/site-packages/MySQLdb/connections.py", line 195, in __init__
    super().__init__(*args, **kwargs2)
MySQLdb.OperationalError: (2005, "Unknown server host 'mysql' (-2)")
[2025-06-15T08:49:29.920+0000] {taskinstance.py:1206} INFO - Marking task as FAILED. dag_id=globalsuperstore, task_id=extract.extract_and_load_to_staging, run_id=scheduled__2025-02-17T00:00:00+00:00, execution_date=20250217T000000, start_date=20250615T084925, end_date=20250615T084929
[2025-06-15T08:49:29.930+0000] {standard_task_runner.py:110} ERROR - Failed to execute job 259 for task extract.extract_and_load_to_staging ((2005, "Unknown server host 'mysql' (-2)"); 1750)
[2025-06-15T08:49:29.955+0000] {local_task_job_runner.py:240} INFO - Task exited with return code 1
[2025-06-15T08:49:29.978+0000] {taskinstance.py:3503} INFO - 0 downstream tasks scheduled from follow-on schedule check
[2025-06-15T08:49:29.985+0000] {local_task_job_runner.py:222} INFO - ::endgroup::
