[2025-06-15T08:45:46.336+0000] {local_task_job_runner.py:120} INFO - ::group::Pre task execution logs
[2025-06-15T08:45:46.422+0000] {taskinstance.py:2076} INFO - Dependencies all met for dep_context=non-requeueable deps ti=<TaskInstance: globalsuperstore.extract.extract_and_load_to_staging scheduled__2024-12-08T00:00:00+00:00 [queued]>
[2025-06-15T08:45:46.437+0000] {taskinstance.py:2076} INFO - Dependencies all met for dep_context=requeueable deps ti=<TaskInstance: globalsuperstore.extract.extract_and_load_to_staging scheduled__2024-12-08T00:00:00+00:00 [queued]>
[2025-06-15T08:45:46.438+0000] {taskinstance.py:2306} INFO - Starting attempt 1 of 1
[2025-06-15T08:45:46.459+0000] {taskinstance.py:2330} INFO - Executing <Task(PythonOperator): extract.extract_and_load_to_staging> on 2024-12-08 00:00:00+00:00
[2025-06-15T08:45:46.484+0000] {standard_task_runner.py:63} INFO - Started process 1411 to run task
[2025-06-15T08:45:46.490+0000] {standard_task_runner.py:90} INFO - Running: ['***', 'tasks', 'run', 'globalsuperstore', 'extract.extract_and_load_to_staging', 'scheduled__2024-12-08T00:00:00+00:00', '--job-id', '158', '--raw', '--subdir', 'DAGS_FOLDER/global_superstore_dw_etl.py', '--cfg-path', '/tmp/tmp1qcyiwl5']
[2025-06-15T08:45:46.495+0000] {standard_task_runner.py:91} INFO - Job 158: Subtask extract.extract_and_load_to_staging
[2025-06-15T08:45:46.575+0000] {task_command.py:426} INFO - Running <TaskInstance: globalsuperstore.extract.extract_and_load_to_staging scheduled__2024-12-08T00:00:00+00:00 [running]> on host f3cca4675eb8
[2025-06-15T08:45:46.759+0000] {taskinstance.py:2648} INFO - Exporting env vars: AIRFLOW_CTX_DAG_OWNER='***' AIRFLOW_CTX_DAG_ID='globalsuperstore' AIRFLOW_CTX_TASK_ID='extract.extract_and_load_to_staging' AIRFLOW_CTX_EXECUTION_DATE='2024-12-08T00:00:00+00:00' AIRFLOW_CTX_TRY_NUMBER='1' AIRFLOW_CTX_DAG_RUN_ID='scheduled__2024-12-08T00:00:00+00:00'
[2025-06-15T08:45:46.763+0000] {taskinstance.py:430} INFO - ::endgroup::
[2025-06-15T08:45:46.814+0000] {base.py:84} INFO - Using connection ID 'postgres' for task execution.
[2025-06-15T08:45:46.831+0000] {base.py:84} INFO - Using connection ID 'mysql' for task execution.
[2025-06-15T08:45:46.872+0000] {logging_mixin.py:188} WARNING - /home/***/.local/lib/python3.10/site-packages/***/providers/common/sql/hooks/sql.py:263 UserWarning: pandas only supports SQLAlchemy connectable (engine/connection) or database string URI or sqlite3 DBAPI2 connection. Other DBAPI2 objects are not tested. Please consider using SQLAlchemy.
[2025-06-15T08:45:46.994+0000] {taskinstance.py:441} INFO - ::group::Post task execution logs
[2025-06-15T08:45:46.997+0000] {taskinstance.py:2905} ERROR - Task failed with exception
Traceback (most recent call last):
  File "/home/airflow/.local/lib/python3.10/site-packages/sqlalchemy/engine/base.py", line 1910, in _execute_context
    self.dialect.do_execute(
  File "/home/airflow/.local/lib/python3.10/site-packages/sqlalchemy/engine/default.py", line 736, in do_execute
    cursor.execute(statement, parameters)
psycopg2.errors.UndefinedTable: table "stg_Category" does not exist


The above exception was the direct cause of the following exception:

Traceback (most recent call last):
  File "/home/airflow/.local/lib/python3.10/site-packages/airflow/models/taskinstance.py", line 465, in _execute_task
    result = _execute_callable(context=context, **execute_callable_kwargs)
  File "/home/airflow/.local/lib/python3.10/site-packages/airflow/models/taskinstance.py", line 432, in _execute_callable
    return execute_callable(context=context, **execute_callable_kwargs)
  File "/home/airflow/.local/lib/python3.10/site-packages/airflow/models/baseoperator.py", line 401, in wrapper
    return func(self, *args, **kwargs)
  File "/home/airflow/.local/lib/python3.10/site-packages/airflow/operators/python.py", line 235, in execute
    return_value = self.execute_callable()
  File "/home/airflow/.local/lib/python3.10/site-packages/airflow/operators/python.py", line 252, in execute_callable
    return self.python_callable(*self.op_args, **self.op_kwargs)
  File "/opt/airflow/dags/extract_data.py", line 27, in extract_and_load_to_staging
    staging_operator.save_data_to_postgres(
  File "/opt/airflow/plugins/postgresql_operator.py", line 24, in save_data_to_postgres
    df.to_sql(
  File "/home/airflow/.local/lib/python3.10/site-packages/pandas/core/generic.py", line 2987, in to_sql
    return sql.to_sql(
  File "/home/airflow/.local/lib/python3.10/site-packages/pandas/io/sql.py", line 695, in to_sql
    return pandas_sql.to_sql(
  File "/home/airflow/.local/lib/python3.10/site-packages/pandas/io/sql.py", line 1728, in to_sql
    table = self.prep_table(
  File "/home/airflow/.local/lib/python3.10/site-packages/pandas/io/sql.py", line 1631, in prep_table
    table.create()
  File "/home/airflow/.local/lib/python3.10/site-packages/pandas/io/sql.py", line 831, in create
    self.pd_sql.drop_table(self.name, self.schema)
  File "/home/airflow/.local/lib/python3.10/site-packages/pandas/io/sql.py", line 1782, in drop_table
    self.get_table(table_name, schema).drop(bind=self.connectable)
  File "/home/airflow/.local/lib/python3.10/site-packages/sqlalchemy/sql/schema.py", line 979, in drop
    bind._run_ddl_visitor(ddl.SchemaDropper, self, checkfirst=checkfirst)
  File "/home/airflow/.local/lib/python3.10/site-packages/sqlalchemy/engine/base.py", line 3238, in _run_ddl_visitor
    conn._run_ddl_visitor(visitorcallable, element, **kwargs)
  File "/home/airflow/.local/lib/python3.10/site-packages/sqlalchemy/engine/base.py", line 2221, in _run_ddl_visitor
    visitorcallable(self.dialect, self, **kwargs).traverse_single(element)
  File "/home/airflow/.local/lib/python3.10/site-packages/sqlalchemy/sql/visitors.py", line 524, in traverse_single
    return meth(obj, **kw)
  File "/home/airflow/.local/lib/python3.10/site-packages/sqlalchemy/sql/ddl.py", line 1106, in visit_table
    self.connection.execute(DropTable(table))
  File "/home/airflow/.local/lib/python3.10/site-packages/sqlalchemy/engine/base.py", line 1385, in execute
    return meth(self, multiparams, params, _EMPTY_EXECUTION_OPTS)
  File "/home/airflow/.local/lib/python3.10/site-packages/sqlalchemy/sql/ddl.py", line 80, in _execute_on_connection
    return connection._execute_ddl(
  File "/home/airflow/.local/lib/python3.10/site-packages/sqlalchemy/engine/base.py", line 1477, in _execute_ddl
    ret = self._execute_context(
  File "/home/airflow/.local/lib/python3.10/site-packages/sqlalchemy/engine/base.py", line 1953, in _execute_context
    self._handle_dbapi_exception(
  File "/home/airflow/.local/lib/python3.10/site-packages/sqlalchemy/engine/base.py", line 2134, in _handle_dbapi_exception
    util.raise_(
  File "/home/airflow/.local/lib/python3.10/site-packages/sqlalchemy/util/compat.py", line 211, in raise_
    raise exception
  File "/home/airflow/.local/lib/python3.10/site-packages/sqlalchemy/engine/base.py", line 1910, in _execute_context
    self.dialect.do_execute(
  File "/home/airflow/.local/lib/python3.10/site-packages/sqlalchemy/engine/default.py", line 736, in do_execute
    cursor.execute(statement, parameters)
sqlalchemy.exc.ProgrammingError: (psycopg2.errors.UndefinedTable) table "stg_Category" does not exist

[SQL: 
DROP TABLE staging."stg_Category"]
(Background on this error at: https://sqlalche.me/e/14/f405)
[2025-06-15T08:45:47.050+0000] {taskinstance.py:1206} INFO - Marking task as FAILED. dag_id=globalsuperstore, task_id=extract.extract_and_load_to_staging, run_id=scheduled__2024-12-08T00:00:00+00:00, execution_date=20241208T000000, start_date=20250615T084546, end_date=20250615T084547
[2025-06-15T08:45:47.094+0000] {standard_task_runner.py:110} ERROR - Failed to execute job 158 for task extract.extract_and_load_to_staging ((psycopg2.errors.UndefinedTable) table "stg_Category" does not exist

[SQL: 
DROP TABLE staging."stg_Category"]
(Background on this error at: https://sqlalche.me/e/14/f405); 1411)
[2025-06-15T08:45:47.150+0000] {local_task_job_runner.py:240} INFO - Task exited with return code 1
[2025-06-15T08:45:47.171+0000] {local_task_job_runner.py:222} INFO - ::endgroup::
