[2025-06-14T01:07:41.090+0000] {local_task_job_runner.py:120} INFO - ::group::Pre task execution logs
[2025-06-14T01:07:41.137+0000] {taskinstance.py:2076} INFO - Dependencies all met for dep_context=non-requeueable deps ti=<TaskInstance: GlobalSuperStore_dw_etl.extract.extract_and_load_to_staging scheduled__2025-06-13T00:00:00+00:00 [queued]>
[2025-06-14T01:07:41.150+0000] {taskinstance.py:2076} INFO - Dependencies all met for dep_context=requeueable deps ti=<TaskInstance: GlobalSuperStore_dw_etl.extract.extract_and_load_to_staging scheduled__2025-06-13T00:00:00+00:00 [queued]>
[2025-06-14T01:07:41.152+0000] {taskinstance.py:2306} INFO - Starting attempt 1 of 1
[2025-06-14T01:07:41.171+0000] {taskinstance.py:2330} INFO - Executing <Task(PythonOperator): extract.extract_and_load_to_staging> on 2025-06-13 00:00:00+00:00
[2025-06-14T01:07:41.178+0000] {standard_task_runner.py:63} INFO - Started process 205 to run task
[2025-06-14T01:07:41.181+0000] {standard_task_runner.py:90} INFO - Running: ['***', 'tasks', 'run', 'GlobalSuperStore_dw_etl', 'extract.extract_and_load_to_staging', 'scheduled__2025-06-13T00:00:00+00:00', '--job-id', '80', '--raw', '--subdir', 'DAGS_FOLDER/globalSuperstore.py', '--cfg-path', '/tmp/tmpkr4hntre']
[2025-06-14T01:07:41.184+0000] {standard_task_runner.py:91} INFO - Job 80: Subtask extract.extract_and_load_to_staging
[2025-06-14T01:07:41.245+0000] {task_command.py:426} INFO - Running <TaskInstance: GlobalSuperStore_dw_etl.extract.extract_and_load_to_staging scheduled__2025-06-13T00:00:00+00:00 [running]> on host ce8c7e7a2a87
[2025-06-14T01:07:41.369+0000] {taskinstance.py:2648} INFO - Exporting env vars: AIRFLOW_CTX_DAG_OWNER='***' AIRFLOW_CTX_DAG_ID='GlobalSuperStore_dw_etl' AIRFLOW_CTX_TASK_ID='extract.extract_and_load_to_staging' AIRFLOW_CTX_EXECUTION_DATE='2025-06-13T00:00:00+00:00' AIRFLOW_CTX_TRY_NUMBER='1' AIRFLOW_CTX_DAG_RUN_ID='scheduled__2025-06-13T00:00:00+00:00'
[2025-06-14T01:07:41.370+0000] {taskinstance.py:430} INFO - ::endgroup::
[2025-06-14T01:07:41.401+0000] {base.py:84} INFO - Using connection ID 'mysql' for task execution.
[2025-06-14T01:07:53.254+0000] {taskinstance.py:441} INFO - ::group::Post task execution logs
[2025-06-14T01:07:53.256+0000] {taskinstance.py:2905} ERROR - Task failed with exception
Traceback (most recent call last):
  File "/home/airflow/.local/lib/python3.10/site-packages/airflow/models/taskinstance.py", line 465, in _execute_task
    result = _execute_callable(context=context, **execute_callable_kwargs)
  File "/home/airflow/.local/lib/python3.10/site-packages/airflow/models/taskinstance.py", line 432, in _execute_callable
    return execute_callable(context=context, **execute_callable_kwargs)
  File "/home/airflow/.local/lib/python3.10/site-packages/airflow/models/baseoperator.py", line 401, in wrapper
    return func(self, *args, **kwargs)
  File "/home/airflow/.local/lib/python3.10/site-packages/airflow/operators/python.py", line 235, in execute
    return_value = self.execute_callable()
  File "/home/airflow/.local/lib/python3.10/site-packages/airflow/operators/python.py", line 252, in execute_callable
    return self.python_callable(*self.op_args, **self.op_kwargs)
  File "/opt/airflow/dags/extract_data.py", line 26, in extract_and_load_to_staging
    df = source_operator.get_data_to_pd(f"SELECT * FROM {table}")
  File "/opt/airflow/plugins/mysql_operator.py", line 15, in get_data_to_pd
    return self.mysqlhook.get_pandas_df(query)
  File "/home/airflow/.local/lib/python3.10/site-packages/airflow/providers/common/sql/hooks/sql.py", line 262, in get_pandas_df
    with closing(self.get_conn()) as conn:
  File "/home/airflow/.local/lib/python3.10/site-packages/airflow/providers/mysql/hooks/mysql.py", line 196, in get_conn
    return MySQLdb.connect(**conn_config)
  File "/home/airflow/.local/lib/python3.10/site-packages/MySQLdb/__init__.py", line 121, in Connect
    return Connection(*args, **kwargs)
  File "/home/airflow/.local/lib/python3.10/site-packages/MySQLdb/connections.py", line 195, in __init__
    super().__init__(*args, **kwargs2)
MySQLdb.OperationalError: (2005, "Unknown server host 'mysql' (-2)")
[2025-06-14T01:07:53.273+0000] {taskinstance.py:1206} INFO - Marking task as FAILED. dag_id=GlobalSuperStore_dw_etl, task_id=extract.extract_and_load_to_staging, run_id=scheduled__2025-06-13T00:00:00+00:00, execution_date=20250613T000000, start_date=20250614T010741, end_date=20250614T010753
[2025-06-14T01:07:53.293+0000] {standard_task_runner.py:110} ERROR - Failed to execute job 80 for task extract.extract_and_load_to_staging ((2005, "Unknown server host 'mysql' (-2)"); 205)
[2025-06-14T01:07:53.332+0000] {local_task_job_runner.py:240} INFO - Task exited with return code 1
[2025-06-14T01:07:53.351+0000] {taskinstance.py:3503} INFO - 0 downstream tasks scheduled from follow-on schedule check
[2025-06-14T01:07:53.356+0000] {local_task_job_runner.py:222} INFO - ::endgroup::
[2025-06-14T01:25:56.647+0000] {local_task_job_runner.py:120} INFO - ::group::Pre task execution logs
[2025-06-14T01:25:56.689+0000] {taskinstance.py:2076} INFO - Dependencies all met for dep_context=non-requeueable deps ti=<TaskInstance: GlobalSuperStore_dw_etl.extract.extract_and_load_to_staging scheduled__2025-06-13T00:00:00+00:00 [queued]>
[2025-06-14T01:25:56.698+0000] {taskinstance.py:2076} INFO - Dependencies all met for dep_context=requeueable deps ti=<TaskInstance: GlobalSuperStore_dw_etl.extract.extract_and_load_to_staging scheduled__2025-06-13T00:00:00+00:00 [queued]>
[2025-06-14T01:25:56.699+0000] {taskinstance.py:2306} INFO - Starting attempt 1 of 1
[2025-06-14T01:25:56.713+0000] {taskinstance.py:2330} INFO - Executing <Task(PythonOperator): extract.extract_and_load_to_staging> on 2025-06-13 00:00:00+00:00
[2025-06-14T01:25:56.718+0000] {standard_task_runner.py:63} INFO - Started process 210 to run task
[2025-06-14T01:25:56.722+0000] {standard_task_runner.py:90} INFO - Running: ['***', 'tasks', 'run', 'GlobalSuperStore_dw_etl', 'extract.extract_and_load_to_staging', 'scheduled__2025-06-13T00:00:00+00:00', '--job-id', '88', '--raw', '--subdir', 'DAGS_FOLDER/globalSuperstore.py', '--cfg-path', '/tmp/tmprffgttfz']
[2025-06-14T01:25:56.725+0000] {standard_task_runner.py:91} INFO - Job 88: Subtask extract.extract_and_load_to_staging
[2025-06-14T01:25:56.781+0000] {task_command.py:426} INFO - Running <TaskInstance: GlobalSuperStore_dw_etl.extract.extract_and_load_to_staging scheduled__2025-06-13T00:00:00+00:00 [running]> on host ce8c7e7a2a87
[2025-06-14T01:25:56.877+0000] {taskinstance.py:2648} INFO - Exporting env vars: AIRFLOW_CTX_DAG_OWNER='***' AIRFLOW_CTX_DAG_ID='GlobalSuperStore_dw_etl' AIRFLOW_CTX_TASK_ID='extract.extract_and_load_to_staging' AIRFLOW_CTX_EXECUTION_DATE='2025-06-13T00:00:00+00:00' AIRFLOW_CTX_TRY_NUMBER='1' AIRFLOW_CTX_DAG_RUN_ID='scheduled__2025-06-13T00:00:00+00:00'
[2025-06-14T01:25:56.878+0000] {taskinstance.py:430} INFO - ::endgroup::
[2025-06-14T01:25:56.909+0000] {base.py:84} INFO - Using connection ID 'postgres' for task execution.
[2025-06-14T01:25:56.921+0000] {base.py:84} INFO - Using connection ID 'mysql' for task execution.
[2025-06-14T01:25:57.009+0000] {logging_mixin.py:188} WARNING - /home/***/.local/lib/python3.10/site-packages/***/providers/common/sql/hooks/sql.py:263 UserWarning: pandas only supports SQLAlchemy connectable (engine/connection) or database string URI or sqlite3 DBAPI2 connection. Other DBAPI2 objects are not tested. Please consider using SQLAlchemy.
[2025-06-14T01:25:57.299+0000] {logging_mixin.py:188} INFO - ✔ Đã load Category → staging.stg_Category
[2025-06-14T01:25:57.304+0000] {base.py:84} INFO - Using connection ID 'mysql' for task execution.
[2025-06-14T01:25:57.308+0000] {logging_mixin.py:188} WARNING - /home/***/.local/lib/python3.10/site-packages/***/providers/common/sql/hooks/sql.py:263 UserWarning: pandas only supports SQLAlchemy connectable (engine/connection) or database string URI or sqlite3 DBAPI2 connection. Other DBAPI2 objects are not tested. Please consider using SQLAlchemy.
[2025-06-14T01:25:58.068+0000] {logging_mixin.py:188} INFO - ✔ Đã load Customer → staging.stg_Customer
[2025-06-14T01:25:58.075+0000] {base.py:84} INFO - Using connection ID 'mysql' for task execution.
[2025-06-14T01:25:58.080+0000] {logging_mixin.py:188} WARNING - /home/***/.local/lib/python3.10/site-packages/***/providers/common/sql/hooks/sql.py:263 UserWarning: pandas only supports SQLAlchemy connectable (engine/connection) or database string URI or sqlite3 DBAPI2 connection. Other DBAPI2 objects are not tested. Please consider using SQLAlchemy.
[2025-06-14T01:26:06.386+0000] {logging_mixin.py:188} INFO - ✔ Đã load Order_Details → staging.stg_Order_Details
[2025-06-14T01:26:06.392+0000] {base.py:84} INFO - Using connection ID 'mysql' for task execution.
[2025-06-14T01:26:06.401+0000] {logging_mixin.py:188} WARNING - /home/***/.local/lib/python3.10/site-packages/***/providers/common/sql/hooks/sql.py:263 UserWarning: pandas only supports SQLAlchemy connectable (engine/connection) or database string URI or sqlite3 DBAPI2 connection. Other DBAPI2 objects are not tested. Please consider using SQLAlchemy.
[2025-06-14T01:26:10.539+0000] {logging_mixin.py:188} INFO - ✔ Đã load Orders → staging.stg_Orders
[2025-06-14T01:26:10.548+0000] {base.py:84} INFO - Using connection ID 'mysql' for task execution.
[2025-06-14T01:26:10.552+0000] {logging_mixin.py:188} WARNING - /home/***/.local/lib/python3.10/site-packages/***/providers/common/sql/hooks/sql.py:263 UserWarning: pandas only supports SQLAlchemy connectable (engine/connection) or database string URI or sqlite3 DBAPI2 connection. Other DBAPI2 objects are not tested. Please consider using SQLAlchemy.
[2025-06-14T01:26:11.462+0000] {logging_mixin.py:188} INFO - ✔ Đã load Product → staging.stg_Product
[2025-06-14T01:26:11.467+0000] {base.py:84} INFO - Using connection ID 'mysql' for task execution.
[2025-06-14T01:26:11.471+0000] {logging_mixin.py:188} WARNING - /home/***/.local/lib/python3.10/site-packages/***/providers/common/sql/hooks/sql.py:263 UserWarning: pandas only supports SQLAlchemy connectable (engine/connection) or database string URI or sqlite3 DBAPI2 connection. Other DBAPI2 objects are not tested. Please consider using SQLAlchemy.
[2025-06-14T01:26:11.488+0000] {logging_mixin.py:188} INFO - ✔ Đã load Sub_Category → staging.stg_Sub_Category
[2025-06-14T01:26:11.489+0000] {python.py:237} INFO - Done. Returned value was: None
[2025-06-14T01:26:11.489+0000] {taskinstance.py:441} INFO - ::group::Post task execution logs
[2025-06-14T01:26:11.496+0000] {taskinstance.py:1206} INFO - Marking task as SUCCESS. dag_id=GlobalSuperStore_dw_etl, task_id=extract.extract_and_load_to_staging, run_id=scheduled__2025-06-13T00:00:00+00:00, execution_date=20250613T000000, start_date=20250614T012556, end_date=20250614T012611
[2025-06-14T01:26:11.544+0000] {local_task_job_runner.py:240} INFO - Task exited with return code 0
[2025-06-14T01:26:11.558+0000] {taskinstance.py:3503} INFO - 0 downstream tasks scheduled from follow-on schedule check
[2025-06-14T01:26:11.560+0000] {local_task_job_runner.py:222} INFO - ::endgroup::
[2025-06-14T08:20:10.453+0000] {local_task_job_runner.py:120} INFO - ::group::Pre task execution logs
[2025-06-14T08:20:10.644+0000] {taskinstance.py:2076} INFO - Dependencies all met for dep_context=non-requeueable deps ti=<TaskInstance: GlobalSuperStore_dw_etl.extract.extract_and_load_to_staging scheduled__2025-06-13T00:00:00+00:00 [queued]>
[2025-06-14T08:20:10.656+0000] {taskinstance.py:2076} INFO - Dependencies all met for dep_context=requeueable deps ti=<TaskInstance: GlobalSuperStore_dw_etl.extract.extract_and_load_to_staging scheduled__2025-06-13T00:00:00+00:00 [queued]>
[2025-06-14T08:20:10.656+0000] {taskinstance.py:2306} INFO - Starting attempt 1 of 1
[2025-06-14T08:20:10.675+0000] {taskinstance.py:2330} INFO - Executing <Task(PythonOperator): extract.extract_and_load_to_staging> on 2025-06-13 00:00:00+00:00
[2025-06-14T08:20:10.680+0000] {standard_task_runner.py:63} INFO - Started process 319 to run task
[2025-06-14T08:20:10.690+0000] {standard_task_runner.py:90} INFO - Running: ['***', 'tasks', 'run', 'GlobalSuperStore_dw_etl', 'extract.extract_and_load_to_staging', 'scheduled__2025-06-13T00:00:00+00:00', '--job-id', '2', '--raw', '--subdir', 'DAGS_FOLDER/global_superstore_dw_etl.py', '--cfg-path', '/tmp/tmpft93qiv6']
[2025-06-14T08:20:10.693+0000] {standard_task_runner.py:91} INFO - Job 2: Subtask extract.extract_and_load_to_staging
[2025-06-14T08:20:10.768+0000] {task_command.py:426} INFO - Running <TaskInstance: GlobalSuperStore_dw_etl.extract.extract_and_load_to_staging scheduled__2025-06-13T00:00:00+00:00 [running]> on host 180404561e2e
[2025-06-14T08:20:10.962+0000] {taskinstance.py:2648} INFO - Exporting env vars: AIRFLOW_CTX_DAG_OWNER='***' AIRFLOW_CTX_DAG_ID='GlobalSuperStore_dw_etl' AIRFLOW_CTX_TASK_ID='extract.extract_and_load_to_staging' AIRFLOW_CTX_EXECUTION_DATE='2025-06-13T00:00:00+00:00' AIRFLOW_CTX_TRY_NUMBER='1' AIRFLOW_CTX_DAG_RUN_ID='scheduled__2025-06-13T00:00:00+00:00'
[2025-06-14T08:20:10.964+0000] {taskinstance.py:430} INFO - ::endgroup::
[2025-06-14T08:20:11.709+0000] {base.py:84} INFO - Using connection ID 'postgres' for task execution.
[2025-06-14T08:20:11.721+0000] {base.py:84} INFO - Using connection ID 'mysql' for task execution.
[2025-06-14T08:20:11.873+0000] {logging_mixin.py:188} WARNING - /home/***/.local/lib/python3.10/site-packages/***/providers/common/sql/hooks/sql.py:263 UserWarning: pandas only supports SQLAlchemy connectable (engine/connection) or database string URI or sqlite3 DBAPI2 connection. Other DBAPI2 objects are not tested. Please consider using SQLAlchemy.
[2025-06-14T08:20:11.970+0000] {taskinstance.py:441} INFO - ::group::Post task execution logs
[2025-06-14T08:20:11.971+0000] {taskinstance.py:2905} ERROR - Task failed with exception
Traceback (most recent call last):
  File "/home/airflow/.local/lib/python3.10/site-packages/pandas/io/sql.py", line 2018, in execute
    cur.execute(*args, **kwargs)
  File "/home/airflow/.local/lib/python3.10/site-packages/MySQLdb/cursors.py", line 179, in execute
    res = self._query(mogrified_query)
  File "/home/airflow/.local/lib/python3.10/site-packages/MySQLdb/cursors.py", line 330, in _query
    db.query(q)
  File "/home/airflow/.local/lib/python3.10/site-packages/MySQLdb/connections.py", line 261, in query
    _mysql.connection.query(self, query)
MySQLdb.ProgrammingError: (1146, "Table 'globalSuperstore.Category' doesn't exist")

The above exception was the direct cause of the following exception:

Traceback (most recent call last):
  File "/home/airflow/.local/lib/python3.10/site-packages/airflow/models/taskinstance.py", line 465, in _execute_task
    result = _execute_callable(context=context, **execute_callable_kwargs)
  File "/home/airflow/.local/lib/python3.10/site-packages/airflow/models/taskinstance.py", line 432, in _execute_callable
    return execute_callable(context=context, **execute_callable_kwargs)
  File "/home/airflow/.local/lib/python3.10/site-packages/airflow/models/baseoperator.py", line 401, in wrapper
    return func(self, *args, **kwargs)
  File "/home/airflow/.local/lib/python3.10/site-packages/airflow/operators/python.py", line 235, in execute
    return_value = self.execute_callable()
  File "/home/airflow/.local/lib/python3.10/site-packages/airflow/operators/python.py", line 252, in execute_callable
    return self.python_callable(*self.op_args, **self.op_kwargs)
  File "/opt/airflow/dags/extract_data.py", line 25, in extract_and_load_to_staging
    df = source_operator.get_data_to_pd(f"SELECT * FROM {table}")
  File "/opt/airflow/plugins/mysql_operator.py", line 15, in get_data_to_pd
    return self.mysqlhook.get_pandas_df(query)
  File "/home/airflow/.local/lib/python3.10/site-packages/airflow/providers/common/sql/hooks/sql.py", line 263, in get_pandas_df
    return psql.read_sql(sql, con=conn, params=parameters, **kwargs)
  File "/home/airflow/.local/lib/python3.10/site-packages/pandas/io/sql.py", line 564, in read_sql
    return pandas_sql.read_query(
  File "/home/airflow/.local/lib/python3.10/site-packages/pandas/io/sql.py", line 2078, in read_query
    cursor = self.execute(*args)
  File "/home/airflow/.local/lib/python3.10/site-packages/pandas/io/sql.py", line 2030, in execute
    raise ex from exc
pandas.errors.DatabaseError: Execution failed on sql 'SELECT * FROM Category': (1146, "Table 'globalSuperstore.Category' doesn't exist")
[2025-06-14T08:20:12.012+0000] {taskinstance.py:1206} INFO - Marking task as FAILED. dag_id=GlobalSuperStore_dw_etl, task_id=extract.extract_and_load_to_staging, run_id=scheduled__2025-06-13T00:00:00+00:00, execution_date=20250613T000000, start_date=20250614T082010, end_date=20250614T082012
[2025-06-14T08:20:12.037+0000] {standard_task_runner.py:110} ERROR - Failed to execute job 2 for task extract.extract_and_load_to_staging (Execution failed on sql 'SELECT * FROM Category': (1146, "Table 'globalSuperstore.Category' doesn't exist"); 319)
[2025-06-14T08:20:12.069+0000] {local_task_job_runner.py:240} INFO - Task exited with return code 1
[2025-06-14T08:20:12.090+0000] {taskinstance.py:3503} INFO - 0 downstream tasks scheduled from follow-on schedule check
[2025-06-14T08:20:12.095+0000] {local_task_job_runner.py:222} INFO - ::endgroup::
[2025-06-14T09:15:30.181+0000] {local_task_job_runner.py:120} INFO - ::group::Pre task execution logs
[2025-06-14T09:15:30.461+0000] {taskinstance.py:2076} INFO - Dependencies all met for dep_context=non-requeueable deps ti=<TaskInstance: GlobalSuperStore_dw_etl.extract.extract_and_load_to_staging scheduled__2025-06-13T00:00:00+00:00 [queued]>
[2025-06-14T09:15:30.478+0000] {taskinstance.py:2076} INFO - Dependencies all met for dep_context=requeueable deps ti=<TaskInstance: GlobalSuperStore_dw_etl.extract.extract_and_load_to_staging scheduled__2025-06-13T00:00:00+00:00 [queued]>
[2025-06-14T09:15:30.479+0000] {taskinstance.py:2306} INFO - Starting attempt 1 of 1
[2025-06-14T09:15:30.512+0000] {taskinstance.py:2330} INFO - Executing <Task(PythonOperator): extract.extract_and_load_to_staging> on 2025-06-13 00:00:00+00:00
[2025-06-14T09:15:30.531+0000] {standard_task_runner.py:63} INFO - Started process 610 to run task
[2025-06-14T09:15:30.537+0000] {standard_task_runner.py:90} INFO - Running: ['***', 'tasks', 'run', 'GlobalSuperStore_dw_etl', 'extract.extract_and_load_to_staging', 'scheduled__2025-06-13T00:00:00+00:00', '--job-id', '18', '--raw', '--subdir', 'DAGS_FOLDER/global_superstore_dw_etl.py', '--cfg-path', '/tmp/tmp8cdrd_id']
[2025-06-14T09:15:30.541+0000] {standard_task_runner.py:91} INFO - Job 18: Subtask extract.extract_and_load_to_staging
[2025-06-14T09:15:30.630+0000] {task_command.py:426} INFO - Running <TaskInstance: GlobalSuperStore_dw_etl.extract.extract_and_load_to_staging scheduled__2025-06-13T00:00:00+00:00 [running]> on host f3cca4675eb8
[2025-06-14T09:15:30.827+0000] {taskinstance.py:2648} INFO - Exporting env vars: AIRFLOW_CTX_DAG_OWNER='***' AIRFLOW_CTX_DAG_ID='GlobalSuperStore_dw_etl' AIRFLOW_CTX_TASK_ID='extract.extract_and_load_to_staging' AIRFLOW_CTX_EXECUTION_DATE='2025-06-13T00:00:00+00:00' AIRFLOW_CTX_TRY_NUMBER='1' AIRFLOW_CTX_DAG_RUN_ID='scheduled__2025-06-13T00:00:00+00:00'
[2025-06-14T09:15:30.829+0000] {taskinstance.py:430} INFO - ::endgroup::
[2025-06-14T09:15:35.112+0000] {base.py:84} INFO - Using connection ID 'postgres' for task execution.
[2025-06-14T09:15:35.121+0000] {base.py:84} INFO - Using connection ID 'mysql' for task execution.
[2025-06-14T09:15:35.459+0000] {logging_mixin.py:188} WARNING - /home/***/.local/lib/python3.10/site-packages/***/providers/common/sql/hooks/sql.py:263 UserWarning: pandas only supports SQLAlchemy connectable (engine/connection) or database string URI or sqlite3 DBAPI2 connection. Other DBAPI2 objects are not tested. Please consider using SQLAlchemy.
[2025-06-14T09:15:35.944+0000] {logging_mixin.py:188} INFO - ✔ Đã load Category → staging.stg_Category
[2025-06-14T09:15:35.951+0000] {base.py:84} INFO - Using connection ID 'mysql' for task execution.
[2025-06-14T09:15:35.959+0000] {logging_mixin.py:188} WARNING - /home/***/.local/lib/python3.10/site-packages/***/providers/common/sql/hooks/sql.py:263 UserWarning: pandas only supports SQLAlchemy connectable (engine/connection) or database string URI or sqlite3 DBAPI2 connection. Other DBAPI2 objects are not tested. Please consider using SQLAlchemy.
[2025-06-14T09:15:36.247+0000] {logging_mixin.py:188} INFO - ✔ Đã load Customer → staging.stg_Customer
[2025-06-14T09:15:36.252+0000] {base.py:84} INFO - Using connection ID 'mysql' for task execution.
[2025-06-14T09:15:36.259+0000] {logging_mixin.py:188} WARNING - /home/***/.local/lib/python3.10/site-packages/***/providers/common/sql/hooks/sql.py:263 UserWarning: pandas only supports SQLAlchemy connectable (engine/connection) or database string URI or sqlite3 DBAPI2 connection. Other DBAPI2 objects are not tested. Please consider using SQLAlchemy.
[2025-06-14T09:15:51.520+0000] {logging_mixin.py:188} INFO - ✔ Đã load Order_Details → staging.stg_Order_Details
[2025-06-14T09:15:51.555+0000] {base.py:84} INFO - Using connection ID 'mysql' for task execution.
[2025-06-14T09:15:51.585+0000] {logging_mixin.py:188} WARNING - /home/***/.local/lib/python3.10/site-packages/***/providers/common/sql/hooks/sql.py:263 UserWarning: pandas only supports SQLAlchemy connectable (engine/connection) or database string URI or sqlite3 DBAPI2 connection. Other DBAPI2 objects are not tested. Please consider using SQLAlchemy.
[2025-06-14T09:15:56.257+0000] {logging_mixin.py:188} INFO - ✔ Đã load Orders → staging.stg_Orders
[2025-06-14T09:15:56.264+0000] {base.py:84} INFO - Using connection ID 'mysql' for task execution.
[2025-06-14T09:15:56.270+0000] {logging_mixin.py:188} WARNING - /home/***/.local/lib/python3.10/site-packages/***/providers/common/sql/hooks/sql.py:263 UserWarning: pandas only supports SQLAlchemy connectable (engine/connection) or database string URI or sqlite3 DBAPI2 connection. Other DBAPI2 objects are not tested. Please consider using SQLAlchemy.
[2025-06-14T09:15:57.424+0000] {logging_mixin.py:188} INFO - ✔ Đã load Product → staging.stg_Product
[2025-06-14T09:15:57.429+0000] {base.py:84} INFO - Using connection ID 'mysql' for task execution.
[2025-06-14T09:15:57.439+0000] {logging_mixin.py:188} WARNING - /home/***/.local/lib/python3.10/site-packages/***/providers/common/sql/hooks/sql.py:263 UserWarning: pandas only supports SQLAlchemy connectable (engine/connection) or database string URI or sqlite3 DBAPI2 connection. Other DBAPI2 objects are not tested. Please consider using SQLAlchemy.
[2025-06-14T09:15:57.864+0000] {logging_mixin.py:188} INFO - ✔ Đã load Sub_Category → staging.stg_Sub_Category
[2025-06-14T09:15:57.872+0000] {python.py:237} INFO - Done. Returned value was: None
[2025-06-14T09:15:57.873+0000] {taskinstance.py:441} INFO - ::group::Post task execution logs
[2025-06-14T09:15:57.883+0000] {taskinstance.py:1206} INFO - Marking task as SUCCESS. dag_id=GlobalSuperStore_dw_etl, task_id=extract.extract_and_load_to_staging, run_id=scheduled__2025-06-13T00:00:00+00:00, execution_date=20250613T000000, start_date=20250614T091530, end_date=20250614T091557
[2025-06-14T09:15:58.019+0000] {local_task_job_runner.py:240} INFO - Task exited with return code 0
[2025-06-14T09:15:58.074+0000] {taskinstance.py:3503} INFO - 1 downstream tasks scheduled from follow-on schedule check
[2025-06-14T09:15:58.147+0000] {local_task_job_runner.py:222} INFO - ::endgroup::
