[2025-06-13T15:17:44.185+0000] {local_task_job_runner.py:120} INFO - ::group::Pre task execution logs
[2025-06-13T15:17:44.374+0000] {taskinstance.py:2076} INFO - Dependencies all met for dep_context=non-requeueable deps ti=<TaskInstance: GlobalSuperStore_dw_etl.extract.extract_and_load_to_staging scheduled__2024-11-15T00:00:00+00:00 [queued]>
[2025-06-13T15:17:44.409+0000] {taskinstance.py:2076} INFO - Dependencies all met for dep_context=requeueable deps ti=<TaskInstance: GlobalSuperStore_dw_etl.extract.extract_and_load_to_staging scheduled__2024-11-15T00:00:00+00:00 [queued]>
[2025-06-13T15:17:44.415+0000] {taskinstance.py:2306} INFO - Starting attempt 1 of 1
[2025-06-13T15:17:44.543+0000] {taskinstance.py:2330} INFO - Executing <Task(PythonOperator): extract.extract_and_load_to_staging> on 2024-11-15 00:00:00+00:00
[2025-06-13T15:17:44.599+0000] {standard_task_runner.py:63} INFO - Started process 454 to run task
[2025-06-13T15:17:44.733+0000] {standard_task_runner.py:90} INFO - Running: ['***', 'tasks', 'run', 'GlobalSuperStore_dw_etl', 'extract.extract_and_load_to_staging', 'scheduled__2024-11-15T00:00:00+00:00', '--job-id', '25', '--raw', '--subdir', 'DAGS_FOLDER/globalSuperstore.py', '--cfg-path', '/tmp/tmptm3avje0']
[2025-06-13T15:17:44.842+0000] {standard_task_runner.py:91} INFO - Job 25: Subtask extract.extract_and_load_to_staging
[2025-06-13T15:17:45.430+0000] {task_command.py:426} INFO - Running <TaskInstance: GlobalSuperStore_dw_etl.extract.extract_and_load_to_staging scheduled__2024-11-15T00:00:00+00:00 [running]> on host e90be8120eaa
[2025-06-13T15:17:53.167+0000] {taskinstance.py:2648} INFO - Exporting env vars: AIRFLOW_CTX_DAG_OWNER='***' AIRFLOW_CTX_DAG_ID='GlobalSuperStore_dw_etl' AIRFLOW_CTX_TASK_ID='extract.extract_and_load_to_staging' AIRFLOW_CTX_EXECUTION_DATE='2024-11-15T00:00:00+00:00' AIRFLOW_CTX_TRY_NUMBER='1' AIRFLOW_CTX_DAG_RUN_ID='scheduled__2024-11-15T00:00:00+00:00'
[2025-06-13T15:17:53.179+0000] {taskinstance.py:430} INFO - ::endgroup::
[2025-06-13T15:17:53.319+0000] {base.py:84} INFO - Using connection ID 'mysql' for task execution.
[2025-06-13T15:17:55.109+0000] {taskinstance.py:441} INFO - ::group::Post task execution logs
[2025-06-13T15:17:55.112+0000] {taskinstance.py:2905} ERROR - Task failed with exception
Traceback (most recent call last):
  File "/home/airflow/.local/lib/python3.10/site-packages/airflow/models/taskinstance.py", line 465, in _execute_task
    result = _execute_callable(context=context, **execute_callable_kwargs)
  File "/home/airflow/.local/lib/python3.10/site-packages/airflow/models/taskinstance.py", line 432, in _execute_callable
    return execute_callable(context=context, **execute_callable_kwargs)
  File "/home/airflow/.local/lib/python3.10/site-packages/airflow/models/baseoperator.py", line 401, in wrapper
    return func(self, *args, **kwargs)
  File "/home/airflow/.local/lib/python3.10/site-packages/airflow/operators/python.py", line 235, in execute
    return_value = self.execute_callable()
  File "/home/airflow/.local/lib/python3.10/site-packages/airflow/operators/python.py", line 252, in execute_callable
    return self.python_callable(*self.op_args, **self.op_kwargs)
  File "/opt/airflow/dags/extract_data.py", line 26, in extract_and_load_to_staging
    df = source_operator.get_data_to_pd(f"SELECT * FROM {table}")
  File "/opt/airflow/plugins/mysql_operator.py", line 14, in get_data_to_pd
    return self.mysqlhook.get_pandas_df(query)
  File "/home/airflow/.local/lib/python3.10/site-packages/airflow/providers/common/sql/hooks/sql.py", line 262, in get_pandas_df
    with closing(self.get_conn()) as conn:
  File "/home/airflow/.local/lib/python3.10/site-packages/airflow/providers/mysql/hooks/mysql.py", line 196, in get_conn
    return MySQLdb.connect(**conn_config)
  File "/home/airflow/.local/lib/python3.10/site-packages/MySQLdb/__init__.py", line 121, in Connect
    return Connection(*args, **kwargs)
  File "/home/airflow/.local/lib/python3.10/site-packages/MySQLdb/connections.py", line 195, in __init__
    super().__init__(*args, **kwargs2)
MySQLdb.OperationalError: (1044, "Access denied for user '***'@'%' to database 'mysql'")
[2025-06-13T15:17:55.169+0000] {taskinstance.py:1206} INFO - Marking task as FAILED. dag_id=GlobalSuperStore_dw_etl, task_id=extract.extract_and_load_to_staging, run_id=scheduled__2024-11-15T00:00:00+00:00, execution_date=20241115T000000, start_date=20250613T151744, end_date=20250613T151755
[2025-06-13T15:17:55.202+0000] {standard_task_runner.py:110} ERROR - Failed to execute job 25 for task extract.extract_and_load_to_staging ((1044, "Access denied for user '***'@'%' to database 'mysql'"); 454)
[2025-06-13T15:17:55.284+0000] {local_task_job_runner.py:240} INFO - Task exited with return code 1
[2025-06-13T15:17:55.355+0000] {local_task_job_runner.py:222} INFO - ::endgroup::
