[2025-06-15T16:58:35.862+0000] {taskinstance.py:1042} DEBUG - previous_execution_date was called
[2025-06-15T16:58:35.887+0000] {__init__.py:54} DEBUG - Loading core task runner: StandardTaskRunner
[2025-06-15T16:58:35.906+0000] {taskinstance.py:1042} DEBUG - previous_execution_date was called
[2025-06-15T16:58:35.915+0000] {base_task_runner.py:73} DEBUG - Planning to run as the  user
[2025-06-15T16:58:35.923+0000] {local_task_job_runner.py:120} INFO - ::group::Pre task execution logs
[2025-06-15T16:58:35.953+0000] {taskinstance.py:2088} DEBUG - <TaskInstance: globalsuperstore.load.transform_fact_sales manual__2025-06-15T16:57:44.945298+00:00 [queued]> dependency 'Task Instance State' PASSED: True, Task state queued was valid.
[2025-06-15T16:58:35.960+0000] {taskinstance.py:2088} DEBUG - <TaskInstance: globalsuperstore.load.transform_fact_sales manual__2025-06-15T16:57:44.945298+00:00 [queued]> dependency 'Previous Dagrun State' PASSED: True, The task did not have depends_on_past set.
[2025-06-15T16:58:35.961+0000] {taskinstance.py:2088} DEBUG - <TaskInstance: globalsuperstore.load.transform_fact_sales manual__2025-06-15T16:57:44.945298+00:00 [queued]> dependency 'Task Instance Not Running' PASSED: True, Task is not in running state.
[2025-06-15T16:58:35.962+0000] {taskinstance.py:2088} DEBUG - <TaskInstance: globalsuperstore.load.transform_fact_sales manual__2025-06-15T16:57:44.945298+00:00 [queued]> dependency 'Not In Retry Period' PASSED: True, The task instance was not marked for retrying.
[2025-06-15T16:58:35.962+0000] {taskinstance.py:2076} INFO - Dependencies all met for dep_context=non-requeueable deps ti=<TaskInstance: globalsuperstore.load.transform_fact_sales manual__2025-06-15T16:57:44.945298+00:00 [queued]>
[2025-06-15T16:58:35.966+0000] {taskinstance.py:2088} DEBUG - <TaskInstance: globalsuperstore.load.transform_fact_sales manual__2025-06-15T16:57:44.945298+00:00 [queued]> dependency 'Previous Dagrun State' PASSED: True, The task did not have depends_on_past set.
[2025-06-15T16:58:35.973+0000] {taskinstance.py:2088} DEBUG - <TaskInstance: globalsuperstore.load.transform_fact_sales manual__2025-06-15T16:57:44.945298+00:00 [queued]> dependency 'Pool Slots Available' PASSED: True, There are enough open slots in default_pool to execute the task
[2025-06-15T16:58:35.973+0000] {taskinstance.py:2088} DEBUG - <TaskInstance: globalsuperstore.load.transform_fact_sales manual__2025-06-15T16:57:44.945298+00:00 [queued]> dependency 'Task Concurrency' PASSED: True, Task concurrency is not set.
[2025-06-15T16:58:35.976+0000] {taskinstance.py:2088} DEBUG - <TaskInstance: globalsuperstore.load.transform_fact_sales manual__2025-06-15T16:57:44.945298+00:00 [queued]> dependency 'Not In Retry Period' PASSED: True, The task instance was not marked for retrying.
[2025-06-15T16:58:35.976+0000] {taskinstance.py:2076} INFO - Dependencies all met for dep_context=requeueable deps ti=<TaskInstance: globalsuperstore.load.transform_fact_sales manual__2025-06-15T16:57:44.945298+00:00 [queued]>
[2025-06-15T16:58:35.977+0000] {taskinstance.py:2306} INFO - Starting attempt 1 of 1
[2025-06-15T16:58:35.995+0000] {taskinstance.py:2330} INFO - Executing <Task(PythonOperator): load.transform_fact_sales> on 2025-06-15 16:57:44.945298+00:00
[2025-06-15T16:58:36.002+0000] {standard_task_runner.py:63} INFO - Started process 411 to run task
[2025-06-15T16:58:36.005+0000] {standard_task_runner.py:90} INFO - Running: ['***', 'tasks', 'run', 'globalsuperstore', 'load.transform_fact_sales', 'manual__2025-06-15T16:57:44.945298+00:00', '--job-id', '112', '--raw', '--subdir', 'DAGS_FOLDER/global_superstore_dw_etl.py', '--cfg-path', '/tmp/tmpih1z2ksq']
[2025-06-15T16:58:36.007+0000] {standard_task_runner.py:91} INFO - Job 112: Subtask load.transform_fact_sales
[2025-06-15T16:58:36.007+0000] {cli_action_loggers.py:70} DEBUG - Calling callbacks: [<function default_action_log at 0x7f2bfbd29750>]
[2025-06-15T16:58:36.062+0000] {taskinstance.py:1042} DEBUG - previous_execution_date was called
[2025-06-15T16:58:36.072+0000] {task_command.py:426} INFO - Running <TaskInstance: globalsuperstore.load.transform_fact_sales manual__2025-06-15T16:57:44.945298+00:00 [running]> on host a40e01b9e58f
[2025-06-15T16:58:36.073+0000] {settings.py:363} DEBUG - Disposing DB connection pool (PID 411)
[2025-06-15T16:58:36.074+0000] {settings.py:250} DEBUG - Setting up DB connection pool (PID 411)
[2025-06-15T16:58:36.074+0000] {settings.py:298} DEBUG - settings.prepare_engine_args(): Using NullPool
[2025-06-15T16:58:36.121+0000] {taskinstance.py:1042} DEBUG - previous_execution_date was called
[2025-06-15T16:58:36.130+0000] {taskinstance.py:1845} DEBUG - Clearing XCom data
[2025-06-15T16:58:36.146+0000] {retries.py:91} DEBUG - Running RenderedTaskInstanceFields.write with retries. Try 1 of 3
[2025-06-15T16:58:36.168+0000] {retries.py:91} DEBUG - Running RenderedTaskInstanceFields._do_delete_old_records with retries. Try 1 of 3
[2025-06-15T16:58:36.178+0000] {taskinstance.py:2648} INFO - Exporting env vars: AIRFLOW_CTX_DAG_OWNER='***' AIRFLOW_CTX_DAG_ID='globalsuperstore' AIRFLOW_CTX_TASK_ID='load.transform_fact_sales' AIRFLOW_CTX_EXECUTION_DATE='2025-06-15T16:57:44.945298+00:00' AIRFLOW_CTX_TRY_NUMBER='1' AIRFLOW_CTX_DAG_RUN_ID='manual__2025-06-15T16:57:44.945298+00:00'
[2025-06-15T16:58:36.179+0000] {__init__.py:115} DEBUG - Preparing lineage inlets and outlets
[2025-06-15T16:58:36.179+0000] {__init__.py:154} DEBUG - inlets: [], outlets: []
[2025-06-15T16:58:36.180+0000] {taskinstance.py:430} INFO - ::endgroup::
[2025-06-15T16:58:36.202+0000] {base.py:84} INFO - Using connection ID 'postgres' for task execution.
[2025-06-15T16:58:36.214+0000] {base.py:84} INFO - Using connection ID 'postgres' for task execution.
[2025-06-15T16:58:36.225+0000] {base.py:84} INFO - Using connection ID 'postgres' for task execution.
[2025-06-15T16:58:36.237+0000] {logging_mixin.py:188} WARNING - /home/***/.local/lib/python3.10/site-packages/***/providers/common/sql/hooks/sql.py:263 UserWarning: pandas only supports SQLAlchemy connectable (engine/connection) or database string URI or sqlite3 DBAPI2 connection. Other DBAPI2 objects are not tested. Please consider using SQLAlchemy.
[2025-06-15T16:58:36.346+0000] {base.py:84} INFO - Using connection ID 'postgres' for task execution.
[2025-06-15T16:58:36.353+0000] {logging_mixin.py:188} WARNING - /home/***/.local/lib/python3.10/site-packages/***/providers/common/sql/hooks/sql.py:263 UserWarning: pandas only supports SQLAlchemy connectable (engine/connection) or database string URI or sqlite3 DBAPI2 connection. Other DBAPI2 objects are not tested. Please consider using SQLAlchemy.
[2025-06-15T16:58:36.697+0000] {base.py:84} INFO - Using connection ID 'postgres' for task execution.
[2025-06-15T16:58:36.706+0000] {logging_mixin.py:188} WARNING - /home/***/.local/lib/python3.10/site-packages/***/providers/common/sql/hooks/sql.py:263 UserWarning: pandas only supports SQLAlchemy connectable (engine/connection) or database string URI or sqlite3 DBAPI2 connection. Other DBAPI2 objects are not tested. Please consider using SQLAlchemy.
[2025-06-15T16:58:36.724+0000] {base.py:84} INFO - Using connection ID 'postgres' for task execution.
[2025-06-15T16:58:36.730+0000] {logging_mixin.py:188} WARNING - /home/***/.local/lib/python3.10/site-packages/***/providers/common/sql/hooks/sql.py:263 UserWarning: pandas only supports SQLAlchemy connectable (engine/connection) or database string URI or sqlite3 DBAPI2 connection. Other DBAPI2 objects are not tested. Please consider using SQLAlchemy.
[2025-06-15T16:58:36.741+0000] {base.py:84} INFO - Using connection ID 'postgres' for task execution.
[2025-06-15T16:58:36.746+0000] {logging_mixin.py:188} WARNING - /home/***/.local/lib/python3.10/site-packages/***/providers/common/sql/hooks/sql.py:263 UserWarning: pandas only supports SQLAlchemy connectable (engine/connection) or database string URI or sqlite3 DBAPI2 connection. Other DBAPI2 objects are not tested. Please consider using SQLAlchemy.
[2025-06-15T16:58:36.766+0000] {base.py:84} INFO - Using connection ID 'postgres' for task execution.
[2025-06-15T16:58:36.772+0000] {logging_mixin.py:188} WARNING - /home/***/.local/lib/python3.10/site-packages/***/providers/common/sql/hooks/sql.py:263 UserWarning: pandas only supports SQLAlchemy connectable (engine/connection) or database string URI or sqlite3 DBAPI2 connection. Other DBAPI2 objects are not tested. Please consider using SQLAlchemy.
[2025-06-15T16:58:41.038+0000] {retries.py:91} DEBUG - Running Job._fetch_from_db with retries. Try 1 of 3
[2025-06-15T16:58:41.051+0000] {retries.py:91} DEBUG - Running Job._update_heartbeat with retries. Try 1 of 3
[2025-06-15T16:58:41.072+0000] {job.py:214} DEBUG - [heartbeat]
[2025-06-15T16:58:46.107+0000] {retries.py:91} DEBUG - Running Job._fetch_from_db with retries. Try 1 of 3
[2025-06-15T16:58:46.159+0000] {retries.py:91} DEBUG - Running Job._update_heartbeat with retries. Try 1 of 3
[2025-06-15T16:58:46.216+0000] {job.py:214} DEBUG - [heartbeat]
[2025-06-15T16:58:51.222+0000] {retries.py:91} DEBUG - Running Job._fetch_from_db with retries. Try 1 of 3
[2025-06-15T16:58:51.233+0000] {retries.py:91} DEBUG - Running Job._update_heartbeat with retries. Try 1 of 3
[2025-06-15T16:58:51.248+0000] {job.py:214} DEBUG - [heartbeat]
[2025-06-15T16:58:56.284+0000] {retries.py:91} DEBUG - Running Job._fetch_from_db with retries. Try 1 of 3
[2025-06-15T16:58:57.007+0000] {retries.py:91} DEBUG - Running Job._update_heartbeat with retries. Try 1 of 3
[2025-06-15T16:58:57.315+0000] {job.py:214} DEBUG - [heartbeat]
[2025-06-15T16:58:59.430+0000] {logging_mixin.py:188} INFO - ✔ Đã transform và lưu dữ liệu vào warehouse.fact_sales
[2025-06-15T16:58:59.516+0000] {python.py:237} INFO - Done. Returned value was: None
[2025-06-15T16:58:59.518+0000] {taskinstance.py:441} INFO - ::group::Post task execution logs
[2025-06-15T16:58:59.520+0000] {__init__.py:77} DEBUG - Lineage called with inlets: [], outlets: []
[2025-06-15T16:58:59.546+0000] {taskinstance.py:584} DEBUG - Clearing next_method and next_kwargs.
[2025-06-15T16:58:59.547+0000] {taskinstance.py:1206} INFO - Marking task as SUCCESS. dag_id=globalsuperstore, task_id=load.transform_fact_sales, run_id=manual__2025-06-15T16:57:44.945298+00:00, execution_date=20250615T165744, start_date=20250615T165835, end_date=20250615T165859
[2025-06-15T16:58:59.551+0000] {taskinstance.py:562} DEBUG - Task Duration set to 23.583632
[2025-06-15T16:58:59.633+0000] {cli_action_loggers.py:88} DEBUG - Calling callbacks: []
[2025-06-15T16:58:59.701+0000] {local_task_job_runner.py:240} INFO - Task exited with return code 0
[2025-06-15T16:58:59.741+0000] {dagrun.py:931} DEBUG - number of tis tasks for <DagRun globalsuperstore @ 2025-06-15 16:57:44.945298+00:00: manual__2025-06-15T16:57:44.945298+00:00, state:running, queued_at: 2025-06-15 16:57:45.220889+00:00. externally triggered: True>: 0 task(s)
[2025-06-15T16:58:59.743+0000] {taskinstance.py:3503} INFO - 0 downstream tasks scheduled from follow-on schedule check
[2025-06-15T16:58:59.788+0000] {local_task_job_runner.py:222} INFO - ::endgroup::
