[2025-06-16T14:17:29.439+0000] {taskinstance.py:1042} DEBUG - previous_execution_date was called
[2025-06-16T14:17:29.455+0000] {__init__.py:54} DEBUG - Loading core task runner: StandardTaskRunner
[2025-06-16T14:17:29.465+0000] {taskinstance.py:1042} DEBUG - previous_execution_date was called
[2025-06-16T14:17:29.470+0000] {base_task_runner.py:73} DEBUG - Planning to run as the  user
[2025-06-16T14:17:29.474+0000] {local_task_job_runner.py:120} INFO - ::group::Pre task execution logs
[2025-06-16T14:17:29.501+0000] {taskinstance.py:2088} DEBUG - <TaskInstance: globalsuperstore.extract.extract_and_load_to_staging manual__2025-06-16T14:17:28.849798+00:00 [queued]> dependency 'Task Instance State' PASSED: True, Task state queued was valid.
[2025-06-16T14:17:29.507+0000] {taskinstance.py:2088} DEBUG - <TaskInstance: globalsuperstore.extract.extract_and_load_to_staging manual__2025-06-16T14:17:28.849798+00:00 [queued]> dependency 'Previous Dagrun State' PASSED: True, The task did not have depends_on_past set.
[2025-06-16T14:17:29.508+0000] {taskinstance.py:2088} DEBUG - <TaskInstance: globalsuperstore.extract.extract_and_load_to_staging manual__2025-06-16T14:17:28.849798+00:00 [queued]> dependency 'Not In Retry Period' PASSED: True, The task instance was not marked for retrying.
[2025-06-16T14:17:29.508+0000] {taskinstance.py:2088} DEBUG - <TaskInstance: globalsuperstore.extract.extract_and_load_to_staging manual__2025-06-16T14:17:28.849798+00:00 [queued]> dependency 'Task Instance Not Running' PASSED: True, Task is not in running state.
[2025-06-16T14:17:29.509+0000] {taskinstance.py:2088} DEBUG - <TaskInstance: globalsuperstore.extract.extract_and_load_to_staging manual__2025-06-16T14:17:28.849798+00:00 [queued]> dependency 'Trigger Rule' PASSED: True, The task instance did not have any upstream tasks.
[2025-06-16T14:17:29.509+0000] {taskinstance.py:2076} INFO - Dependencies all met for dep_context=non-requeueable deps ti=<TaskInstance: globalsuperstore.extract.extract_and_load_to_staging manual__2025-06-16T14:17:28.849798+00:00 [queued]>
[2025-06-16T14:17:29.511+0000] {taskinstance.py:2088} DEBUG - <TaskInstance: globalsuperstore.extract.extract_and_load_to_staging manual__2025-06-16T14:17:28.849798+00:00 [queued]> dependency 'Previous Dagrun State' PASSED: True, The task did not have depends_on_past set.
[2025-06-16T14:17:29.513+0000] {taskinstance.py:2088} DEBUG - <TaskInstance: globalsuperstore.extract.extract_and_load_to_staging manual__2025-06-16T14:17:28.849798+00:00 [queued]> dependency 'Not In Retry Period' PASSED: True, The task instance was not marked for retrying.
[2025-06-16T14:17:29.517+0000] {taskinstance.py:2088} DEBUG - <TaskInstance: globalsuperstore.extract.extract_and_load_to_staging manual__2025-06-16T14:17:28.849798+00:00 [queued]> dependency 'Pool Slots Available' PASSED: True, There are enough open slots in default_pool to execute the task
[2025-06-16T14:17:29.518+0000] {taskinstance.py:2088} DEBUG - <TaskInstance: globalsuperstore.extract.extract_and_load_to_staging manual__2025-06-16T14:17:28.849798+00:00 [queued]> dependency 'Task Concurrency' PASSED: True, Task concurrency is not set.
[2025-06-16T14:17:29.518+0000] {taskinstance.py:2088} DEBUG - <TaskInstance: globalsuperstore.extract.extract_and_load_to_staging manual__2025-06-16T14:17:28.849798+00:00 [queued]> dependency 'Trigger Rule' PASSED: True, The task instance did not have any upstream tasks.
[2025-06-16T14:17:29.518+0000] {taskinstance.py:2076} INFO - Dependencies all met for dep_context=requeueable deps ti=<TaskInstance: globalsuperstore.extract.extract_and_load_to_staging manual__2025-06-16T14:17:28.849798+00:00 [queued]>
[2025-06-16T14:17:29.519+0000] {taskinstance.py:2306} INFO - Starting attempt 1 of 1
[2025-06-16T14:17:29.534+0000] {taskinstance.py:2330} INFO - Executing <Task(PythonOperator): extract.extract_and_load_to_staging> on 2025-06-16 14:17:28.849798+00:00
[2025-06-16T14:17:29.540+0000] {standard_task_runner.py:63} INFO - Started process 309 to run task
[2025-06-16T14:17:29.548+0000] {standard_task_runner.py:90} INFO - Running: ['***', 'tasks', 'run', 'globalsuperstore', 'extract.extract_and_load_to_staging', 'manual__2025-06-16T14:17:28.849798+00:00', '--job-id', '5', '--raw', '--subdir', 'DAGS_FOLDER/global_superstore_dw_etl.py', '--cfg-path', '/tmp/tmp2jqzpnky']
[2025-06-16T14:17:29.551+0000] {standard_task_runner.py:91} INFO - Job 5: Subtask extract.extract_and_load_to_staging
[2025-06-16T14:17:29.552+0000] {cli_action_loggers.py:70} DEBUG - Calling callbacks: [<function default_action_log at 0x7fee6db2d750>]
[2025-06-16T14:17:29.596+0000] {taskinstance.py:1042} DEBUG - previous_execution_date was called
[2025-06-16T14:17:29.607+0000] {task_command.py:426} INFO - Running <TaskInstance: globalsuperstore.extract.extract_and_load_to_staging manual__2025-06-16T14:17:28.849798+00:00 [running]> on host cdd5f2df74dd
[2025-06-16T14:17:29.608+0000] {settings.py:363} DEBUG - Disposing DB connection pool (PID 309)
[2025-06-16T14:17:29.609+0000] {settings.py:250} DEBUG - Setting up DB connection pool (PID 309)
[2025-06-16T14:17:29.610+0000] {settings.py:298} DEBUG - settings.prepare_engine_args(): Using NullPool
[2025-06-16T14:17:29.641+0000] {taskinstance.py:1042} DEBUG - previous_execution_date was called
[2025-06-16T14:17:29.643+0000] {taskinstance.py:1845} DEBUG - Clearing XCom data
[2025-06-16T14:17:29.655+0000] {retries.py:91} DEBUG - Running RenderedTaskInstanceFields.write with retries. Try 1 of 3
[2025-06-16T14:17:29.679+0000] {retries.py:91} DEBUG - Running RenderedTaskInstanceFields._do_delete_old_records with retries. Try 1 of 3
[2025-06-16T14:17:29.691+0000] {taskinstance.py:2648} INFO - Exporting env vars: AIRFLOW_CTX_DAG_OWNER='***' AIRFLOW_CTX_DAG_ID='globalsuperstore' AIRFLOW_CTX_TASK_ID='extract.extract_and_load_to_staging' AIRFLOW_CTX_EXECUTION_DATE='2025-06-16T14:17:28.849798+00:00' AIRFLOW_CTX_TRY_NUMBER='1' AIRFLOW_CTX_DAG_RUN_ID='manual__2025-06-16T14:17:28.849798+00:00'
[2025-06-16T14:17:29.692+0000] {__init__.py:115} DEBUG - Preparing lineage inlets and outlets
[2025-06-16T14:17:29.693+0000] {__init__.py:154} DEBUG - inlets: [], outlets: []
[2025-06-16T14:17:29.693+0000] {taskinstance.py:430} INFO - ::endgroup::
[2025-06-16T14:17:29.716+0000] {base.py:84} INFO - Using connection ID 'postgres' for task execution.
[2025-06-16T14:17:29.723+0000] {base.py:84} INFO - Using connection ID 'mysql' for task execution.
[2025-06-16T14:17:29.739+0000] {logging_mixin.py:188} WARNING - /home/***/.local/lib/python3.10/site-packages/***/providers/common/sql/hooks/sql.py:263 UserWarning: pandas only supports SQLAlchemy connectable (engine/connection) or database string URI or sqlite3 DBAPI2 connection. Other DBAPI2 objects are not tested. Please consider using SQLAlchemy.
[2025-06-16T14:17:29.748+0000] {taskinstance.py:441} INFO - ::group::Post task execution logs
[2025-06-16T14:17:29.755+0000] {taskinstance.py:2905} ERROR - Task failed with exception
Traceback (most recent call last):
  File "/home/airflow/.local/lib/python3.10/site-packages/sqlalchemy/engine/base.py", line 3371, in _wrap_pool_connect
    return fn()
  File "/home/airflow/.local/lib/python3.10/site-packages/sqlalchemy/pool/base.py", line 327, in connect
    return _ConnectionFairy._checkout(self)
  File "/home/airflow/.local/lib/python3.10/site-packages/sqlalchemy/pool/base.py", line 894, in _checkout
    fairy = _ConnectionRecord.checkout(pool)
  File "/home/airflow/.local/lib/python3.10/site-packages/sqlalchemy/pool/base.py", line 493, in checkout
    rec = pool._do_get()
  File "/home/airflow/.local/lib/python3.10/site-packages/sqlalchemy/pool/impl.py", line 145, in _do_get
    with util.safe_reraise():
  File "/home/airflow/.local/lib/python3.10/site-packages/sqlalchemy/util/langhelpers.py", line 70, in __exit__
    compat.raise_(
  File "/home/airflow/.local/lib/python3.10/site-packages/sqlalchemy/util/compat.py", line 211, in raise_
    raise exception
  File "/home/airflow/.local/lib/python3.10/site-packages/sqlalchemy/pool/impl.py", line 143, in _do_get
    return self._create_connection()
  File "/home/airflow/.local/lib/python3.10/site-packages/sqlalchemy/pool/base.py", line 273, in _create_connection
    return _ConnectionRecord(self)
  File "/home/airflow/.local/lib/python3.10/site-packages/sqlalchemy/pool/base.py", line 388, in __init__
    self.__connect()
  File "/home/airflow/.local/lib/python3.10/site-packages/sqlalchemy/pool/base.py", line 690, in __connect
    with util.safe_reraise():
  File "/home/airflow/.local/lib/python3.10/site-packages/sqlalchemy/util/langhelpers.py", line 70, in __exit__
    compat.raise_(
  File "/home/airflow/.local/lib/python3.10/site-packages/sqlalchemy/util/compat.py", line 211, in raise_
    raise exception
  File "/home/airflow/.local/lib/python3.10/site-packages/sqlalchemy/pool/base.py", line 686, in __connect
    self.dbapi_connection = connection = pool._invoke_creator(self)
  File "/home/airflow/.local/lib/python3.10/site-packages/sqlalchemy/engine/create.py", line 574, in connect
    return dialect.connect(*cargs, **cparams)
  File "/home/airflow/.local/lib/python3.10/site-packages/sqlalchemy/engine/default.py", line 598, in connect
    return self.dbapi.connect(*cargs, **cparams)
  File "/home/airflow/.local/lib/python3.10/site-packages/psycopg2/__init__.py", line 122, in connect
    conn = _connect(dsn, connection_factory=connection_factory, **kwasync)
psycopg2.OperationalError: connection to server at "de_psql" (172.18.0.3), port 5432 failed: FATAL:  database "lobalsuperstore" does not exist


The above exception was the direct cause of the following exception:

Traceback (most recent call last):
  File "/home/airflow/.local/lib/python3.10/site-packages/airflow/models/taskinstance.py", line 465, in _execute_task
    result = _execute_callable(context=context, **execute_callable_kwargs)
  File "/home/airflow/.local/lib/python3.10/site-packages/airflow/models/taskinstance.py", line 432, in _execute_callable
    return execute_callable(context=context, **execute_callable_kwargs)
  File "/home/airflow/.local/lib/python3.10/site-packages/airflow/models/baseoperator.py", line 401, in wrapper
    return func(self, *args, **kwargs)
  File "/home/airflow/.local/lib/python3.10/site-packages/airflow/operators/python.py", line 235, in execute
    return_value = self.execute_callable()
  File "/home/airflow/.local/lib/python3.10/site-packages/airflow/operators/python.py", line 252, in execute_callable
    return self.python_callable(*self.op_args, **self.op_kwargs)
  File "/opt/airflow/dags/extract_data.py", line 27, in extract_and_load_to_staging
    staging_operator.save_data_to_postgres(
  File "/opt/airflow/plugins/postgresql_operator.py", line 20, in save_data_to_postgres
    with self.engine.connect() as conn:
  File "/home/airflow/.local/lib/python3.10/site-packages/sqlalchemy/engine/base.py", line 3325, in connect
    return self._connection_cls(self, close_with_result=close_with_result)
  File "/home/airflow/.local/lib/python3.10/site-packages/sqlalchemy/engine/base.py", line 96, in __init__
    else engine.raw_connection()
  File "/home/airflow/.local/lib/python3.10/site-packages/sqlalchemy/engine/base.py", line 3404, in raw_connection
    return self._wrap_pool_connect(self.pool.connect, _connection)
  File "/home/airflow/.local/lib/python3.10/site-packages/sqlalchemy/engine/base.py", line 3374, in _wrap_pool_connect
    Connection._handle_dbapi_exception_noconnection(
  File "/home/airflow/.local/lib/python3.10/site-packages/sqlalchemy/engine/base.py", line 2208, in _handle_dbapi_exception_noconnection
    util.raise_(
  File "/home/airflow/.local/lib/python3.10/site-packages/sqlalchemy/util/compat.py", line 211, in raise_
    raise exception
  File "/home/airflow/.local/lib/python3.10/site-packages/sqlalchemy/engine/base.py", line 3371, in _wrap_pool_connect
    return fn()
  File "/home/airflow/.local/lib/python3.10/site-packages/sqlalchemy/pool/base.py", line 327, in connect
    return _ConnectionFairy._checkout(self)
  File "/home/airflow/.local/lib/python3.10/site-packages/sqlalchemy/pool/base.py", line 894, in _checkout
    fairy = _ConnectionRecord.checkout(pool)
  File "/home/airflow/.local/lib/python3.10/site-packages/sqlalchemy/pool/base.py", line 493, in checkout
    rec = pool._do_get()
  File "/home/airflow/.local/lib/python3.10/site-packages/sqlalchemy/pool/impl.py", line 145, in _do_get
    with util.safe_reraise():
  File "/home/airflow/.local/lib/python3.10/site-packages/sqlalchemy/util/langhelpers.py", line 70, in __exit__
    compat.raise_(
  File "/home/airflow/.local/lib/python3.10/site-packages/sqlalchemy/util/compat.py", line 211, in raise_
    raise exception
  File "/home/airflow/.local/lib/python3.10/site-packages/sqlalchemy/pool/impl.py", line 143, in _do_get
    return self._create_connection()
  File "/home/airflow/.local/lib/python3.10/site-packages/sqlalchemy/pool/base.py", line 273, in _create_connection
    return _ConnectionRecord(self)
  File "/home/airflow/.local/lib/python3.10/site-packages/sqlalchemy/pool/base.py", line 388, in __init__
    self.__connect()
  File "/home/airflow/.local/lib/python3.10/site-packages/sqlalchemy/pool/base.py", line 690, in __connect
    with util.safe_reraise():
  File "/home/airflow/.local/lib/python3.10/site-packages/sqlalchemy/util/langhelpers.py", line 70, in __exit__
    compat.raise_(
  File "/home/airflow/.local/lib/python3.10/site-packages/sqlalchemy/util/compat.py", line 211, in raise_
    raise exception
  File "/home/airflow/.local/lib/python3.10/site-packages/sqlalchemy/pool/base.py", line 686, in __connect
    self.dbapi_connection = connection = pool._invoke_creator(self)
  File "/home/airflow/.local/lib/python3.10/site-packages/sqlalchemy/engine/create.py", line 574, in connect
    return dialect.connect(*cargs, **cparams)
  File "/home/airflow/.local/lib/python3.10/site-packages/sqlalchemy/engine/default.py", line 598, in connect
    return self.dbapi.connect(*cargs, **cparams)
  File "/home/airflow/.local/lib/python3.10/site-packages/psycopg2/__init__.py", line 122, in connect
    conn = _connect(dsn, connection_factory=connection_factory, **kwasync)
sqlalchemy.exc.OperationalError: (psycopg2.OperationalError) connection to server at "de_psql" (172.18.0.3), port 5432 failed: FATAL:  database "lobalsuperstore" does not exist

(Background on this error at: https://sqlalche.me/e/14/e3q8)
[2025-06-16T14:17:29.778+0000] {taskinstance.py:562} DEBUG - Task Duration set to 0.268322
[2025-06-16T14:17:29.788+0000] {taskinstance.py:584} DEBUG - Clearing next_method and next_kwargs.
[2025-06-16T14:17:29.789+0000] {taskinstance.py:1206} INFO - Marking task as FAILED. dag_id=globalsuperstore, task_id=extract.extract_and_load_to_staging, run_id=manual__2025-06-16T14:17:28.849798+00:00, execution_date=20250616T141728, start_date=20250616T141729, end_date=20250616T141729
[2025-06-16T14:17:29.800+0000] {cli_action_loggers.py:88} DEBUG - Calling callbacks: []
[2025-06-16T14:17:29.801+0000] {standard_task_runner.py:110} ERROR - Failed to execute job 5 for task extract.extract_and_load_to_staging ((psycopg2.OperationalError) connection to server at "de_psql" (172.18.0.3), port 5432 failed: FATAL:  database "lobalsuperstore" does not exist

(Background on this error at: https://sqlalche.me/e/14/e3q8); 309)
[2025-06-16T14:17:29.844+0000] {local_task_job_runner.py:240} INFO - Task exited with return code 1
[2025-06-16T14:17:29.863+0000] {dagrun.py:931} DEBUG - number of tis tasks for <DagRun globalsuperstore @ 2025-06-16 14:17:28.849798+00:00: manual__2025-06-16T14:17:28.849798+00:00, state:running, queued_at: 2025-06-16 14:17:28.909778+00:00. externally triggered: True>: 7 task(s)
[2025-06-16T14:17:29.864+0000] {dagrun.py:952} DEBUG - number of scheduleable tasks for <DagRun globalsuperstore @ 2025-06-16 14:17:28.849798+00:00: manual__2025-06-16T14:17:28.849798+00:00, state:running, queued_at: 2025-06-16 14:17:28.909778+00:00. externally triggered: True>: 6 task(s)
[2025-06-16T14:17:29.865+0000] {taskinstance.py:2088} DEBUG - <TaskInstance: globalsuperstore.load.transform_fact_sales manual__2025-06-16T14:17:28.849798+00:00 [None]> dependency 'Not In Retry Period' PASSED: True, The task instance was not marked for retrying.
[2025-06-16T14:17:29.866+0000] {taskinstance.py:2088} DEBUG - <TaskInstance: globalsuperstore.load.transform_fact_sales manual__2025-06-16T14:17:28.849798+00:00 [None]> dependency 'Trigger Rule' PASSED: False, Task's trigger rule 'all_success' requires all upstream tasks to have succeeded, but found 5 non-success(es). upstream_states=_UpstreamTIStates(success=0, skipped=0, failed=0, upstream_failed=0, removed=0, done=0, success_setup=0, skipped_setup=0), upstream_task_ids={'transform.transform_dim_shipmode', 'transform.transform_dim_locations', 'transform.transform_dim_customers', 'transform.transform_dim_products', 'transform.transform_dim_date'}
[2025-06-16T14:17:29.867+0000] {taskinstance.py:2066} DEBUG - Dependencies not met for <TaskInstance: globalsuperstore.load.transform_fact_sales manual__2025-06-16T14:17:28.849798+00:00 [None]>, dependency 'Trigger Rule' FAILED: Task's trigger rule 'all_success' requires all upstream tasks to have succeeded, but found 5 non-success(es). upstream_states=_UpstreamTIStates(success=0, skipped=0, failed=0, upstream_failed=0, removed=0, done=0, success_setup=0, skipped_setup=0), upstream_task_ids={'transform.transform_dim_shipmode', 'transform.transform_dim_locations', 'transform.transform_dim_customers', 'transform.transform_dim_products', 'transform.transform_dim_date'}
[2025-06-16T14:17:29.867+0000] {taskinstance.py:2088} DEBUG - <TaskInstance: globalsuperstore.load.transform_fact_sales manual__2025-06-16T14:17:28.849798+00:00 [None]> dependency 'Previous Dagrun State' PASSED: True, The task did not have depends_on_past set.
[2025-06-16T14:17:29.867+0000] {taskinstance.py:2088} DEBUG - <TaskInstance: globalsuperstore.transform.transform_dim_customers manual__2025-06-16T14:17:28.849798+00:00 [None]> dependency 'Not In Retry Period' PASSED: True, The task instance was not marked for retrying.
[2025-06-16T14:17:29.868+0000] {taskinstance.py:1884} DEBUG - Setting task state for <TaskInstance: globalsuperstore.transform.transform_dim_customers manual__2025-06-16T14:17:28.849798+00:00 [None]> to upstream_failed
[2025-06-16T14:17:29.869+0000] {taskinstance.py:2088} DEBUG - <TaskInstance: globalsuperstore.transform.transform_dim_customers manual__2025-06-16T14:17:28.849798+00:00 [upstream_failed]> dependency 'Trigger Rule' PASSED: False, Task's trigger rule 'all_success' requires all upstream tasks to have succeeded, but found 1 non-success(es). upstream_states=_UpstreamTIStates(success=0, skipped=0, failed=1, upstream_failed=0, removed=0, done=1, success_setup=0, skipped_setup=0), upstream_task_ids={'extract.extract_and_load_to_staging'}
[2025-06-16T14:17:29.869+0000] {taskinstance.py:2066} DEBUG - Dependencies not met for <TaskInstance: globalsuperstore.transform.transform_dim_customers manual__2025-06-16T14:17:28.849798+00:00 [upstream_failed]>, dependency 'Trigger Rule' FAILED: Task's trigger rule 'all_success' requires all upstream tasks to have succeeded, but found 1 non-success(es). upstream_states=_UpstreamTIStates(success=0, skipped=0, failed=1, upstream_failed=0, removed=0, done=1, success_setup=0, skipped_setup=0), upstream_task_ids={'extract.extract_and_load_to_staging'}
[2025-06-16T14:17:29.869+0000] {taskinstance.py:2088} DEBUG - <TaskInstance: globalsuperstore.transform.transform_dim_customers manual__2025-06-16T14:17:28.849798+00:00 [upstream_failed]> dependency 'Previous Dagrun State' PASSED: True, The task did not have depends_on_past set.
[2025-06-16T14:17:29.870+0000] {taskinstance.py:2088} DEBUG - <TaskInstance: globalsuperstore.transform.transform_dim_date manual__2025-06-16T14:17:28.849798+00:00 [None]> dependency 'Not In Retry Period' PASSED: True, The task instance was not marked for retrying.
[2025-06-16T14:17:29.871+0000] {taskinstance.py:1884} DEBUG - Setting task state for <TaskInstance: globalsuperstore.transform.transform_dim_date manual__2025-06-16T14:17:28.849798+00:00 [None]> to upstream_failed
[2025-06-16T14:17:29.871+0000] {taskinstance.py:2088} DEBUG - <TaskInstance: globalsuperstore.transform.transform_dim_date manual__2025-06-16T14:17:28.849798+00:00 [upstream_failed]> dependency 'Trigger Rule' PASSED: False, Task's trigger rule 'all_success' requires all upstream tasks to have succeeded, but found 1 non-success(es). upstream_states=_UpstreamTIStates(success=0, skipped=0, failed=1, upstream_failed=0, removed=0, done=1, success_setup=0, skipped_setup=0), upstream_task_ids={'extract.extract_and_load_to_staging'}
[2025-06-16T14:17:29.871+0000] {taskinstance.py:2066} DEBUG - Dependencies not met for <TaskInstance: globalsuperstore.transform.transform_dim_date manual__2025-06-16T14:17:28.849798+00:00 [upstream_failed]>, dependency 'Trigger Rule' FAILED: Task's trigger rule 'all_success' requires all upstream tasks to have succeeded, but found 1 non-success(es). upstream_states=_UpstreamTIStates(success=0, skipped=0, failed=1, upstream_failed=0, removed=0, done=1, success_setup=0, skipped_setup=0), upstream_task_ids={'extract.extract_and_load_to_staging'}
[2025-06-16T14:17:29.872+0000] {taskinstance.py:2088} DEBUG - <TaskInstance: globalsuperstore.transform.transform_dim_date manual__2025-06-16T14:17:28.849798+00:00 [upstream_failed]> dependency 'Previous Dagrun State' PASSED: True, The task did not have depends_on_past set.
[2025-06-16T14:17:29.872+0000] {taskinstance.py:2088} DEBUG - <TaskInstance: globalsuperstore.transform.transform_dim_locations manual__2025-06-16T14:17:28.849798+00:00 [None]> dependency 'Not In Retry Period' PASSED: True, The task instance was not marked for retrying.
[2025-06-16T14:17:29.873+0000] {taskinstance.py:1884} DEBUG - Setting task state for <TaskInstance: globalsuperstore.transform.transform_dim_locations manual__2025-06-16T14:17:28.849798+00:00 [None]> to upstream_failed
[2025-06-16T14:17:29.873+0000] {taskinstance.py:2088} DEBUG - <TaskInstance: globalsuperstore.transform.transform_dim_locations manual__2025-06-16T14:17:28.849798+00:00 [upstream_failed]> dependency 'Trigger Rule' PASSED: False, Task's trigger rule 'all_success' requires all upstream tasks to have succeeded, but found 1 non-success(es). upstream_states=_UpstreamTIStates(success=0, skipped=0, failed=1, upstream_failed=0, removed=0, done=1, success_setup=0, skipped_setup=0), upstream_task_ids={'extract.extract_and_load_to_staging'}
[2025-06-16T14:17:29.873+0000] {taskinstance.py:2066} DEBUG - Dependencies not met for <TaskInstance: globalsuperstore.transform.transform_dim_locations manual__2025-06-16T14:17:28.849798+00:00 [upstream_failed]>, dependency 'Trigger Rule' FAILED: Task's trigger rule 'all_success' requires all upstream tasks to have succeeded, but found 1 non-success(es). upstream_states=_UpstreamTIStates(success=0, skipped=0, failed=1, upstream_failed=0, removed=0, done=1, success_setup=0, skipped_setup=0), upstream_task_ids={'extract.extract_and_load_to_staging'}
[2025-06-16T14:17:29.874+0000] {taskinstance.py:2088} DEBUG - <TaskInstance: globalsuperstore.transform.transform_dim_locations manual__2025-06-16T14:17:28.849798+00:00 [upstream_failed]> dependency 'Previous Dagrun State' PASSED: True, The task did not have depends_on_past set.
[2025-06-16T14:17:29.874+0000] {taskinstance.py:2088} DEBUG - <TaskInstance: globalsuperstore.transform.transform_dim_products manual__2025-06-16T14:17:28.849798+00:00 [None]> dependency 'Not In Retry Period' PASSED: True, The task instance was not marked for retrying.
[2025-06-16T14:17:29.875+0000] {taskinstance.py:1884} DEBUG - Setting task state for <TaskInstance: globalsuperstore.transform.transform_dim_products manual__2025-06-16T14:17:28.849798+00:00 [None]> to upstream_failed
[2025-06-16T14:17:29.875+0000] {taskinstance.py:2088} DEBUG - <TaskInstance: globalsuperstore.transform.transform_dim_products manual__2025-06-16T14:17:28.849798+00:00 [upstream_failed]> dependency 'Trigger Rule' PASSED: False, Task's trigger rule 'all_success' requires all upstream tasks to have succeeded, but found 1 non-success(es). upstream_states=_UpstreamTIStates(success=0, skipped=0, failed=1, upstream_failed=0, removed=0, done=1, success_setup=0, skipped_setup=0), upstream_task_ids={'extract.extract_and_load_to_staging'}
[2025-06-16T14:17:29.876+0000] {taskinstance.py:2066} DEBUG - Dependencies not met for <TaskInstance: globalsuperstore.transform.transform_dim_products manual__2025-06-16T14:17:28.849798+00:00 [upstream_failed]>, dependency 'Trigger Rule' FAILED: Task's trigger rule 'all_success' requires all upstream tasks to have succeeded, but found 1 non-success(es). upstream_states=_UpstreamTIStates(success=0, skipped=0, failed=1, upstream_failed=0, removed=0, done=1, success_setup=0, skipped_setup=0), upstream_task_ids={'extract.extract_and_load_to_staging'}
[2025-06-16T14:17:29.876+0000] {taskinstance.py:2088} DEBUG - <TaskInstance: globalsuperstore.transform.transform_dim_products manual__2025-06-16T14:17:28.849798+00:00 [upstream_failed]> dependency 'Previous Dagrun State' PASSED: True, The task did not have depends_on_past set.
[2025-06-16T14:17:29.876+0000] {taskinstance.py:2088} DEBUG - <TaskInstance: globalsuperstore.transform.transform_dim_shipmode manual__2025-06-16T14:17:28.849798+00:00 [None]> dependency 'Not In Retry Period' PASSED: True, The task instance was not marked for retrying.
[2025-06-16T14:17:29.877+0000] {taskinstance.py:1884} DEBUG - Setting task state for <TaskInstance: globalsuperstore.transform.transform_dim_shipmode manual__2025-06-16T14:17:28.849798+00:00 [None]> to upstream_failed
[2025-06-16T14:17:29.877+0000] {taskinstance.py:2088} DEBUG - <TaskInstance: globalsuperstore.transform.transform_dim_shipmode manual__2025-06-16T14:17:28.849798+00:00 [upstream_failed]> dependency 'Trigger Rule' PASSED: False, Task's trigger rule 'all_success' requires all upstream tasks to have succeeded, but found 1 non-success(es). upstream_states=_UpstreamTIStates(success=0, skipped=0, failed=1, upstream_failed=0, removed=0, done=1, success_setup=0, skipped_setup=0), upstream_task_ids={'extract.extract_and_load_to_staging'}
[2025-06-16T14:17:29.878+0000] {taskinstance.py:2066} DEBUG - Dependencies not met for <TaskInstance: globalsuperstore.transform.transform_dim_shipmode manual__2025-06-16T14:17:28.849798+00:00 [upstream_failed]>, dependency 'Trigger Rule' FAILED: Task's trigger rule 'all_success' requires all upstream tasks to have succeeded, but found 1 non-success(es). upstream_states=_UpstreamTIStates(success=0, skipped=0, failed=1, upstream_failed=0, removed=0, done=1, success_setup=0, skipped_setup=0), upstream_task_ids={'extract.extract_and_load_to_staging'}
[2025-06-16T14:17:29.878+0000] {taskinstance.py:2088} DEBUG - <TaskInstance: globalsuperstore.transform.transform_dim_shipmode manual__2025-06-16T14:17:28.849798+00:00 [upstream_failed]> dependency 'Previous Dagrun State' PASSED: True, The task did not have depends_on_past set.
[2025-06-16T14:17:29.885+0000] {taskinstance.py:3503} INFO - 0 downstream tasks scheduled from follow-on schedule check
[2025-06-16T14:17:29.894+0000] {local_task_job_runner.py:222} INFO - ::endgroup::
