[2025-06-16T08:47:48.548+0000] {taskinstance.py:1042} DEBUG - previous_execution_date was called
[2025-06-16T08:47:48.576+0000] {__init__.py:54} DEBUG - Loading core task runner: StandardTaskRunner
[2025-06-16T08:47:48.595+0000] {taskinstance.py:1042} DEBUG - previous_execution_date was called
[2025-06-16T08:47:48.604+0000] {base_task_runner.py:73} DEBUG - Planning to run as the  user
[2025-06-16T08:47:48.613+0000] {local_task_job_runner.py:120} INFO - ::group::Pre task execution logs
[2025-06-16T08:47:48.657+0000] {taskinstance.py:2088} DEBUG - <TaskInstance: globalsuperstore.transform.transform_dim_customers manual__2025-06-16T08:47:25.020141+00:00 [queued]> dependency 'Not In Retry Period' PASSED: True, The task instance was not marked for retrying.
[2025-06-16T08:47:48.658+0000] {taskinstance.py:2088} DEBUG - <TaskInstance: globalsuperstore.transform.transform_dim_customers manual__2025-06-16T08:47:25.020141+00:00 [queued]> dependency 'Previous Dagrun State' PASSED: True, The task did not have depends_on_past set.
[2025-06-16T08:47:48.664+0000] {taskinstance.py:2088} DEBUG - <TaskInstance: globalsuperstore.transform.transform_dim_customers manual__2025-06-16T08:47:25.020141+00:00 [queued]> dependency 'Task Instance State' PASSED: True, Task state queued was valid.
[2025-06-16T08:47:48.665+0000] {taskinstance.py:2088} DEBUG - <TaskInstance: globalsuperstore.transform.transform_dim_customers manual__2025-06-16T08:47:25.020141+00:00 [queued]> dependency 'Task Instance Not Running' PASSED: True, Task is not in running state.
[2025-06-16T08:47:48.665+0000] {taskinstance.py:2076} INFO - Dependencies all met for dep_context=non-requeueable deps ti=<TaskInstance: globalsuperstore.transform.transform_dim_customers manual__2025-06-16T08:47:25.020141+00:00 [queued]>
[2025-06-16T08:47:48.666+0000] {taskinstance.py:2088} DEBUG - <TaskInstance: globalsuperstore.transform.transform_dim_customers manual__2025-06-16T08:47:25.020141+00:00 [queued]> dependency 'Not In Retry Period' PASSED: True, The task instance was not marked for retrying.
[2025-06-16T08:47:48.666+0000] {taskinstance.py:2088} DEBUG - <TaskInstance: globalsuperstore.transform.transform_dim_customers manual__2025-06-16T08:47:25.020141+00:00 [queued]> dependency 'Previous Dagrun State' PASSED: True, The task did not have depends_on_past set.
[2025-06-16T08:47:48.672+0000] {taskinstance.py:2088} DEBUG - <TaskInstance: globalsuperstore.transform.transform_dim_customers manual__2025-06-16T08:47:25.020141+00:00 [queued]> dependency 'Pool Slots Available' PASSED: True, There are enough open slots in default_pool to execute the task
[2025-06-16T08:47:48.672+0000] {taskinstance.py:2088} DEBUG - <TaskInstance: globalsuperstore.transform.transform_dim_customers manual__2025-06-16T08:47:25.020141+00:00 [queued]> dependency 'Task Concurrency' PASSED: True, Task concurrency is not set.
[2025-06-16T08:47:48.674+0000] {taskinstance.py:2076} INFO - Dependencies all met for dep_context=requeueable deps ti=<TaskInstance: globalsuperstore.transform.transform_dim_customers manual__2025-06-16T08:47:25.020141+00:00 [queued]>
[2025-06-16T08:47:48.675+0000] {taskinstance.py:2306} INFO - Starting attempt 1 of 1
[2025-06-16T08:47:48.689+0000] {taskinstance.py:2330} INFO - Executing <Task(PythonOperator): transform.transform_dim_customers> on 2025-06-16 08:47:25.020141+00:00
[2025-06-16T08:47:48.704+0000] {standard_task_runner.py:63} INFO - Started process 3618 to run task
[2025-06-16T08:47:48.710+0000] {standard_task_runner.py:90} INFO - Running: ['***', 'tasks', 'run', 'globalsuperstore', 'transform.transform_dim_customers', 'manual__2025-06-16T08:47:25.020141+00:00', '--job-id', '152', '--raw', '--subdir', 'DAGS_FOLDER/global_superstore_dw_etl.py', '--cfg-path', '/tmp/tmpx8_v6n51']
[2025-06-16T08:47:48.712+0000] {standard_task_runner.py:91} INFO - Job 152: Subtask transform.transform_dim_customers
[2025-06-16T08:47:48.713+0000] {cli_action_loggers.py:70} DEBUG - Calling callbacks: [<function default_action_log at 0x7ff936f2d750>]
[2025-06-16T08:47:48.786+0000] {taskinstance.py:1042} DEBUG - previous_execution_date was called
[2025-06-16T08:47:48.795+0000] {task_command.py:426} INFO - Running <TaskInstance: globalsuperstore.transform.transform_dim_customers manual__2025-06-16T08:47:25.020141+00:00 [running]> on host a40e01b9e58f
[2025-06-16T08:47:48.796+0000] {settings.py:363} DEBUG - Disposing DB connection pool (PID 3618)
[2025-06-16T08:47:48.797+0000] {settings.py:250} DEBUG - Setting up DB connection pool (PID 3618)
[2025-06-16T08:47:48.797+0000] {settings.py:298} DEBUG - settings.prepare_engine_args(): Using NullPool
[2025-06-16T08:47:48.837+0000] {taskinstance.py:1042} DEBUG - previous_execution_date was called
[2025-06-16T08:47:48.843+0000] {taskinstance.py:1845} DEBUG - Clearing XCom data
[2025-06-16T08:47:48.870+0000] {retries.py:91} DEBUG - Running RenderedTaskInstanceFields.write with retries. Try 1 of 3
[2025-06-16T08:47:48.912+0000] {retries.py:91} DEBUG - Running RenderedTaskInstanceFields._do_delete_old_records with retries. Try 1 of 3
[2025-06-16T08:47:48.930+0000] {taskinstance.py:2648} INFO - Exporting env vars: AIRFLOW_CTX_DAG_OWNER='***' AIRFLOW_CTX_DAG_ID='globalsuperstore' AIRFLOW_CTX_TASK_ID='transform.transform_dim_customers' AIRFLOW_CTX_EXECUTION_DATE='2025-06-16T08:47:25.020141+00:00' AIRFLOW_CTX_TRY_NUMBER='1' AIRFLOW_CTX_DAG_RUN_ID='manual__2025-06-16T08:47:25.020141+00:00'
[2025-06-16T08:47:48.931+0000] {__init__.py:115} DEBUG - Preparing lineage inlets and outlets
[2025-06-16T08:47:48.932+0000] {__init__.py:154} DEBUG - inlets: [], outlets: []
[2025-06-16T08:47:48.933+0000] {taskinstance.py:430} INFO - ::endgroup::
[2025-06-16T08:47:48.974+0000] {base.py:84} INFO - Using connection ID 'postgres' for task execution.
[2025-06-16T08:47:48.985+0000] {base.py:84} INFO - Using connection ID 'postgres' for task execution.
[2025-06-16T08:47:48.996+0000] {base.py:84} INFO - Using connection ID 'postgres' for task execution.
[2025-06-16T08:47:49.040+0000] {logging_mixin.py:188} WARNING - /home/***/.local/lib/python3.10/site-packages/***/providers/common/sql/hooks/sql.py:263 UserWarning: pandas only supports SQLAlchemy connectable (engine/connection) or database string URI or sqlite3 DBAPI2 connection. Other DBAPI2 objects are not tested. Please consider using SQLAlchemy.
[2025-06-16T08:47:49.137+0000] {taskinstance.py:441} INFO - ::group::Post task execution logs
[2025-06-16T08:47:49.140+0000] {taskinstance.py:2905} ERROR - Task failed with exception
Traceback (most recent call last):
  File "/home/airflow/.local/lib/python3.10/site-packages/sqlalchemy/engine/base.py", line 1910, in _execute_context
    self.dialect.do_execute(
  File "/home/airflow/.local/lib/python3.10/site-packages/sqlalchemy/engine/default.py", line 736, in do_execute
    cursor.execute(statement, parameters)
psycopg2.errors.DependentObjectsStillExist: cannot drop table warehouse.dim_customer because other objects depend on it
DETAIL:  constraint fact_sales_customer_id_fkey on table warehouse.fact_sales depends on table warehouse.dim_customer
HINT:  Use DROP ... CASCADE to drop the dependent objects too.


The above exception was the direct cause of the following exception:

Traceback (most recent call last):
  File "/home/airflow/.local/lib/python3.10/site-packages/airflow/models/taskinstance.py", line 465, in _execute_task
    result = _execute_callable(context=context, **execute_callable_kwargs)
  File "/home/airflow/.local/lib/python3.10/site-packages/airflow/models/taskinstance.py", line 432, in _execute_callable
    return execute_callable(context=context, **execute_callable_kwargs)
  File "/home/airflow/.local/lib/python3.10/site-packages/airflow/models/baseoperator.py", line 401, in wrapper
    return func(self, *args, **kwargs)
  File "/home/airflow/.local/lib/python3.10/site-packages/airflow/operators/python.py", line 235, in execute
    return_value = self.execute_callable()
  File "/home/airflow/.local/lib/python3.10/site-packages/airflow/operators/python.py", line 252, in execute_callable
    return self.python_callable(*self.op_args, **self.op_kwargs)
  File "/opt/airflow/dags/transform_dim_customers.py", line 29, in transform_dim_customers
    warehouse_operator.save_data_to_postgres(
  File "/opt/airflow/plugins/postgresql_operator.py", line 24, in save_data_to_postgres
    con=self.engine,
  File "/home/airflow/.local/lib/python3.10/site-packages/pandas/core/generic.py", line 2987, in to_sql
    return sql.to_sql(
  File "/home/airflow/.local/lib/python3.10/site-packages/pandas/io/sql.py", line 695, in to_sql
    return pandas_sql.to_sql(
  File "/home/airflow/.local/lib/python3.10/site-packages/pandas/io/sql.py", line 1728, in to_sql
    table = self.prep_table(
  File "/home/airflow/.local/lib/python3.10/site-packages/pandas/io/sql.py", line 1631, in prep_table
    table.create()
  File "/home/airflow/.local/lib/python3.10/site-packages/pandas/io/sql.py", line 831, in create
    self.pd_sql.drop_table(self.name, self.schema)
  File "/home/airflow/.local/lib/python3.10/site-packages/pandas/io/sql.py", line 1782, in drop_table
    self.get_table(table_name, schema).drop(bind=self.connectable)
  File "/home/airflow/.local/lib/python3.10/site-packages/sqlalchemy/sql/schema.py", line 979, in drop
    bind._run_ddl_visitor(ddl.SchemaDropper, self, checkfirst=checkfirst)
  File "/home/airflow/.local/lib/python3.10/site-packages/sqlalchemy/engine/base.py", line 3238, in _run_ddl_visitor
    conn._run_ddl_visitor(visitorcallable, element, **kwargs)
  File "/home/airflow/.local/lib/python3.10/site-packages/sqlalchemy/engine/base.py", line 2221, in _run_ddl_visitor
    visitorcallable(self.dialect, self, **kwargs).traverse_single(element)
  File "/home/airflow/.local/lib/python3.10/site-packages/sqlalchemy/sql/visitors.py", line 524, in traverse_single
    return meth(obj, **kw)
  File "/home/airflow/.local/lib/python3.10/site-packages/sqlalchemy/sql/ddl.py", line 1106, in visit_table
    self.connection.execute(DropTable(table))
  File "/home/airflow/.local/lib/python3.10/site-packages/sqlalchemy/engine/base.py", line 1385, in execute
    return meth(self, multiparams, params, _EMPTY_EXECUTION_OPTS)
  File "/home/airflow/.local/lib/python3.10/site-packages/sqlalchemy/sql/ddl.py", line 80, in _execute_on_connection
    return connection._execute_ddl(
  File "/home/airflow/.local/lib/python3.10/site-packages/sqlalchemy/engine/base.py", line 1477, in _execute_ddl
    ret = self._execute_context(
  File "/home/airflow/.local/lib/python3.10/site-packages/sqlalchemy/engine/base.py", line 1953, in _execute_context
    self._handle_dbapi_exception(
  File "/home/airflow/.local/lib/python3.10/site-packages/sqlalchemy/engine/base.py", line 2134, in _handle_dbapi_exception
    util.raise_(
  File "/home/airflow/.local/lib/python3.10/site-packages/sqlalchemy/util/compat.py", line 211, in raise_
    raise exception
  File "/home/airflow/.local/lib/python3.10/site-packages/sqlalchemy/engine/base.py", line 1910, in _execute_context
    self.dialect.do_execute(
  File "/home/airflow/.local/lib/python3.10/site-packages/sqlalchemy/engine/default.py", line 736, in do_execute
    cursor.execute(statement, parameters)
sqlalchemy.exc.InternalError: (psycopg2.errors.DependentObjectsStillExist) cannot drop table warehouse.dim_customer because other objects depend on it
DETAIL:  constraint fact_sales_customer_id_fkey on table warehouse.fact_sales depends on table warehouse.dim_customer
HINT:  Use DROP ... CASCADE to drop the dependent objects too.

[SQL: 
DROP TABLE warehouse.dim_customer]
(Background on this error at: https://sqlalche.me/e/14/2j85)
[2025-06-16T08:47:49.225+0000] {taskinstance.py:562} DEBUG - Task Duration set to 0.558942
[2025-06-16T08:47:49.230+0000] {taskinstance.py:584} DEBUG - Clearing next_method and next_kwargs.
[2025-06-16T08:47:49.232+0000] {taskinstance.py:1206} INFO - Marking task as FAILED. dag_id=globalsuperstore, task_id=transform.transform_dim_customers, run_id=manual__2025-06-16T08:47:25.020141+00:00, execution_date=20250616T084725, start_date=20250616T084748, end_date=20250616T084749
[2025-06-16T08:47:49.275+0000] {cli_action_loggers.py:88} DEBUG - Calling callbacks: []
[2025-06-16T08:47:49.279+0000] {standard_task_runner.py:110} ERROR - Failed to execute job 152 for task transform.transform_dim_customers ((psycopg2.errors.DependentObjectsStillExist) cannot drop table warehouse.dim_customer because other objects depend on it
DETAIL:  constraint fact_sales_customer_id_fkey on table warehouse.fact_sales depends on table warehouse.dim_customer
HINT:  Use DROP ... CASCADE to drop the dependent objects too.

[SQL: 
DROP TABLE warehouse.dim_customer]
(Background on this error at: https://sqlalche.me/e/14/2j85); 3618)
[2025-06-16T08:47:49.326+0000] {local_task_job_runner.py:240} INFO - Task exited with return code 1
[2025-06-16T08:47:49.357+0000] {dagrun.py:931} DEBUG - number of tis tasks for <DagRun globalsuperstore @ 2025-06-16 08:47:25.020141+00:00: manual__2025-06-16T08:47:25.020141+00:00, state:running, queued_at: 2025-06-16 08:47:25.077307+00:00. externally triggered: True>: 6 task(s)
[2025-06-16T08:47:49.358+0000] {dagrun.py:952} DEBUG - number of scheduleable tasks for <DagRun globalsuperstore @ 2025-06-16 08:47:25.020141+00:00: manual__2025-06-16T08:47:25.020141+00:00, state:running, queued_at: 2025-06-16 08:47:25.077307+00:00. externally triggered: True>: 1 task(s)
[2025-06-16T08:47:49.359+0000] {taskinstance.py:2088} DEBUG - <TaskInstance: globalsuperstore.load.transform_fact_sales manual__2025-06-16T08:47:25.020141+00:00 [None]> dependency 'Not In Retry Period' PASSED: True, The task instance was not marked for retrying.
[2025-06-16T08:47:49.359+0000] {taskinstance.py:2088} DEBUG - <TaskInstance: globalsuperstore.load.transform_fact_sales manual__2025-06-16T08:47:25.020141+00:00 [None]> dependency 'Previous Dagrun State' PASSED: True, The task did not have depends_on_past set.
[2025-06-16T08:47:49.361+0000] {taskinstance.py:1884} DEBUG - Setting task state for <TaskInstance: globalsuperstore.load.transform_fact_sales manual__2025-06-16T08:47:25.020141+00:00 [None]> to upstream_failed
[2025-06-16T08:47:49.362+0000] {taskinstance.py:2088} DEBUG - <TaskInstance: globalsuperstore.load.transform_fact_sales manual__2025-06-16T08:47:25.020141+00:00 [upstream_failed]> dependency 'Trigger Rule' PASSED: False, Task's trigger rule 'all_success' requires all upstream tasks to have succeeded, but found 5 non-success(es). upstream_states=_UpstreamTIStates(success=0, skipped=0, failed=3, upstream_failed=0, removed=0, done=3, success_setup=0, skipped_setup=0), upstream_task_ids={'transform.transform_dim_products', 'transform.transform_dim_locations', 'transform.transform_dim_shipmode', 'transform.transform_dim_customers', 'transform.transform_dim_date'}
[2025-06-16T08:47:49.362+0000] {taskinstance.py:2066} DEBUG - Dependencies not met for <TaskInstance: globalsuperstore.load.transform_fact_sales manual__2025-06-16T08:47:25.020141+00:00 [upstream_failed]>, dependency 'Trigger Rule' FAILED: Task's trigger rule 'all_success' requires all upstream tasks to have succeeded, but found 5 non-success(es). upstream_states=_UpstreamTIStates(success=0, skipped=0, failed=3, upstream_failed=0, removed=0, done=3, success_setup=0, skipped_setup=0), upstream_task_ids={'transform.transform_dim_products', 'transform.transform_dim_locations', 'transform.transform_dim_shipmode', 'transform.transform_dim_customers', 'transform.transform_dim_date'}
[2025-06-16T08:47:49.370+0000] {taskinstance.py:3503} INFO - 0 downstream tasks scheduled from follow-on schedule check
[2025-06-16T08:47:49.378+0000] {local_task_job_runner.py:222} INFO - ::endgroup::
