[2025-06-15T08:59:53.276+0000] {local_task_job_runner.py:120} INFO - ::group::Pre task execution logs
[2025-06-15T08:59:53.313+0000] {taskinstance.py:2076} INFO - Dependencies all met for dep_context=non-requeueable deps ti=<TaskInstance: globalsuperstore.load.transform_fact_sales manual__2025-06-15T08:59:07.994118+00:00 [queued]>
[2025-06-15T08:59:53.323+0000] {taskinstance.py:2076} INFO - Dependencies all met for dep_context=requeueable deps ti=<TaskInstance: globalsuperstore.load.transform_fact_sales manual__2025-06-15T08:59:07.994118+00:00 [queued]>
[2025-06-15T08:59:53.325+0000] {taskinstance.py:2306} INFO - Starting attempt 1 of 1
[2025-06-15T08:59:53.340+0000] {taskinstance.py:2330} INFO - Executing <Task(PythonOperator): load.transform_fact_sales> on 2025-06-15 08:59:07.994118+00:00
[2025-06-15T08:59:53.346+0000] {standard_task_runner.py:63} INFO - Started process 389 to run task
[2025-06-15T08:59:53.349+0000] {standard_task_runner.py:90} INFO - Running: ['***', 'tasks', 'run', 'globalsuperstore', 'load.transform_fact_sales', 'manual__2025-06-15T08:59:07.994118+00:00', '--job-id', '314', '--raw', '--subdir', 'DAGS_FOLDER/global_superstore_dw_etl.py', '--cfg-path', '/tmp/tmp3s7hocza']
[2025-06-15T08:59:53.351+0000] {standard_task_runner.py:91} INFO - Job 314: Subtask load.transform_fact_sales
[2025-06-15T08:59:53.411+0000] {task_command.py:426} INFO - Running <TaskInstance: globalsuperstore.load.transform_fact_sales manual__2025-06-15T08:59:07.994118+00:00 [running]> on host f3cca4675eb8
[2025-06-15T08:59:53.504+0000] {taskinstance.py:2648} INFO - Exporting env vars: AIRFLOW_CTX_DAG_OWNER='***' AIRFLOW_CTX_DAG_ID='globalsuperstore' AIRFLOW_CTX_TASK_ID='load.transform_fact_sales' AIRFLOW_CTX_EXECUTION_DATE='2025-06-15T08:59:07.994118+00:00' AIRFLOW_CTX_TRY_NUMBER='1' AIRFLOW_CTX_DAG_RUN_ID='manual__2025-06-15T08:59:07.994118+00:00'
[2025-06-15T08:59:53.506+0000] {taskinstance.py:430} INFO - ::endgroup::
[2025-06-15T08:59:53.527+0000] {base.py:84} INFO - Using connection ID 'postgres' for task execution.
[2025-06-15T08:59:53.533+0000] {base.py:84} INFO - Using connection ID 'postgres' for task execution.
[2025-06-15T08:59:53.540+0000] {base.py:84} INFO - Using connection ID 'postgres' for task execution.
[2025-06-15T08:59:53.553+0000] {logging_mixin.py:188} WARNING - /home/***/.local/lib/python3.10/site-packages/***/providers/common/sql/hooks/sql.py:263 UserWarning: pandas only supports SQLAlchemy connectable (engine/connection) or database string URI or sqlite3 DBAPI2 connection. Other DBAPI2 objects are not tested. Please consider using SQLAlchemy.
[2025-06-15T08:59:53.647+0000] {base.py:84} INFO - Using connection ID 'postgres' for task execution.
[2025-06-15T08:59:53.652+0000] {logging_mixin.py:188} WARNING - /home/***/.local/lib/python3.10/site-packages/***/providers/common/sql/hooks/sql.py:263 UserWarning: pandas only supports SQLAlchemy connectable (engine/connection) or database string URI or sqlite3 DBAPI2 connection. Other DBAPI2 objects are not tested. Please consider using SQLAlchemy.
[2025-06-15T08:59:53.664+0000] {base.py:84} INFO - Using connection ID 'postgres' for task execution.
[2025-06-15T08:59:53.671+0000] {logging_mixin.py:188} WARNING - /home/***/.local/lib/python3.10/site-packages/***/providers/common/sql/hooks/sql.py:263 UserWarning: pandas only supports SQLAlchemy connectable (engine/connection) or database string URI or sqlite3 DBAPI2 connection. Other DBAPI2 objects are not tested. Please consider using SQLAlchemy.
[2025-06-15T08:59:53.684+0000] {base.py:84} INFO - Using connection ID 'postgres' for task execution.
[2025-06-15T08:59:53.693+0000] {logging_mixin.py:188} WARNING - /home/***/.local/lib/python3.10/site-packages/***/providers/common/sql/hooks/sql.py:263 UserWarning: pandas only supports SQLAlchemy connectable (engine/connection) or database string URI or sqlite3 DBAPI2 connection. Other DBAPI2 objects are not tested. Please consider using SQLAlchemy.
[2025-06-15T08:59:53.725+0000] {base.py:84} INFO - Using connection ID 'postgres' for task execution.
[2025-06-15T08:59:53.735+0000] {logging_mixin.py:188} WARNING - /home/***/.local/lib/python3.10/site-packages/***/providers/common/sql/hooks/sql.py:263 UserWarning: pandas only supports SQLAlchemy connectable (engine/connection) or database string URI or sqlite3 DBAPI2 connection. Other DBAPI2 objects are not tested. Please consider using SQLAlchemy.
[2025-06-15T08:59:53.837+0000] {taskinstance.py:441} INFO - ::group::Post task execution logs
[2025-06-15T08:59:53.839+0000] {taskinstance.py:2905} ERROR - Task failed with exception
Traceback (most recent call last):
  File "/home/airflow/.local/lib/python3.10/site-packages/airflow/models/taskinstance.py", line 465, in _execute_task
    result = _execute_callable(context=context, **execute_callable_kwargs)
  File "/home/airflow/.local/lib/python3.10/site-packages/airflow/models/taskinstance.py", line 432, in _execute_callable
    return execute_callable(context=context, **execute_callable_kwargs)
  File "/home/airflow/.local/lib/python3.10/site-packages/airflow/models/baseoperator.py", line 401, in wrapper
    return func(self, *args, **kwargs)
  File "/home/airflow/.local/lib/python3.10/site-packages/airflow/operators/python.py", line 235, in execute
    return_value = self.execute_callable()
  File "/home/airflow/.local/lib/python3.10/site-packages/airflow/operators/python.py", line 252, in execute_callable
    return self.python_callable(*self.op_args, **self.op_kwargs)
  File "/opt/airflow/dags/transform_fact_sales.py", line 37, in transform_fact_sales
    df = df.merge(df_products, how='left',
  File "/home/airflow/.local/lib/python3.10/site-packages/pandas/core/frame.py", line 10093, in merge
    return merge(
  File "/home/airflow/.local/lib/python3.10/site-packages/pandas/core/reshape/merge.py", line 110, in merge
    op = _MergeOperation(
  File "/home/airflow/.local/lib/python3.10/site-packages/pandas/core/reshape/merge.py", line 703, in __init__
    ) = self._get_merge_keys()
  File "/home/airflow/.local/lib/python3.10/site-packages/pandas/core/reshape/merge.py", line 1179, in _get_merge_keys
    left_keys.append(left._get_label_or_level_values(lk))
  File "/home/airflow/.local/lib/python3.10/site-packages/pandas/core/generic.py", line 1850, in _get_label_or_level_values
    raise KeyError(key)
KeyError: 'product_name'
[2025-06-15T08:59:53.872+0000] {taskinstance.py:1206} INFO - Marking task as FAILED. dag_id=globalsuperstore, task_id=load.transform_fact_sales, run_id=manual__2025-06-15T08:59:07.994118+00:00, execution_date=20250615T085907, start_date=20250615T085953, end_date=20250615T085953
[2025-06-15T08:59:53.891+0000] {standard_task_runner.py:110} ERROR - Failed to execute job 314 for task load.transform_fact_sales ('product_name'; 389)
[2025-06-15T08:59:53.923+0000] {local_task_job_runner.py:240} INFO - Task exited with return code 1
[2025-06-15T08:59:53.944+0000] {taskinstance.py:3503} INFO - 0 downstream tasks scheduled from follow-on schedule check
[2025-06-15T08:59:53.948+0000] {local_task_job_runner.py:222} INFO - ::endgroup::
