[2025-06-15T16:50:44.969+0000] {taskinstance.py:1042} DEBUG - previous_execution_date was called
[2025-06-15T16:50:45.030+0000] {__init__.py:54} DEBUG - Loading core task runner: StandardTaskRunner
[2025-06-15T16:50:45.044+0000] {taskinstance.py:1042} DEBUG - previous_execution_date was called
[2025-06-15T16:50:45.052+0000] {base_task_runner.py:73} DEBUG - Planning to run as the  user
[2025-06-15T16:50:45.059+0000] {local_task_job_runner.py:120} INFO - ::group::Pre task execution logs
[2025-06-15T16:50:45.102+0000] {taskinstance.py:2088} DEBUG - <TaskInstance: globalsuperstore.load.transform_fact_sales manual__2025-06-15T16:50:05.830452+00:00 [queued]> dependency 'Task Instance Not Running' PASSED: True, Task is not in running state.
[2025-06-15T16:50:45.103+0000] {taskinstance.py:2088} DEBUG - <TaskInstance: globalsuperstore.load.transform_fact_sales manual__2025-06-15T16:50:05.830452+00:00 [queued]> dependency 'Previous Dagrun State' PASSED: True, The task did not have depends_on_past set.
[2025-06-15T16:50:45.103+0000] {taskinstance.py:2088} DEBUG - <TaskInstance: globalsuperstore.load.transform_fact_sales manual__2025-06-15T16:50:05.830452+00:00 [queued]> dependency 'Task Instance State' PASSED: True, Task state queued was valid.
[2025-06-15T16:50:45.104+0000] {taskinstance.py:2088} DEBUG - <TaskInstance: globalsuperstore.load.transform_fact_sales manual__2025-06-15T16:50:05.830452+00:00 [queued]> dependency 'Not In Retry Period' PASSED: True, The task instance was not marked for retrying.
[2025-06-15T16:50:45.104+0000] {taskinstance.py:2076} INFO - Dependencies all met for dep_context=non-requeueable deps ti=<TaskInstance: globalsuperstore.load.transform_fact_sales manual__2025-06-15T16:50:05.830452+00:00 [queued]>
[2025-06-15T16:50:45.109+0000] {taskinstance.py:2088} DEBUG - <TaskInstance: globalsuperstore.load.transform_fact_sales manual__2025-06-15T16:50:05.830452+00:00 [queued]> dependency 'Task Concurrency' PASSED: True, Task concurrency is not set.
[2025-06-15T16:50:45.114+0000] {taskinstance.py:2088} DEBUG - <TaskInstance: globalsuperstore.load.transform_fact_sales manual__2025-06-15T16:50:05.830452+00:00 [queued]> dependency 'Pool Slots Available' PASSED: True, There are enough open slots in default_pool to execute the task
[2025-06-15T16:50:45.115+0000] {taskinstance.py:2088} DEBUG - <TaskInstance: globalsuperstore.load.transform_fact_sales manual__2025-06-15T16:50:05.830452+00:00 [queued]> dependency 'Previous Dagrun State' PASSED: True, The task did not have depends_on_past set.
[2025-06-15T16:50:45.116+0000] {taskinstance.py:2088} DEBUG - <TaskInstance: globalsuperstore.load.transform_fact_sales manual__2025-06-15T16:50:05.830452+00:00 [queued]> dependency 'Not In Retry Period' PASSED: True, The task instance was not marked for retrying.
[2025-06-15T16:50:45.116+0000] {taskinstance.py:2076} INFO - Dependencies all met for dep_context=requeueable deps ti=<TaskInstance: globalsuperstore.load.transform_fact_sales manual__2025-06-15T16:50:05.830452+00:00 [queued]>
[2025-06-15T16:50:45.117+0000] {taskinstance.py:2306} INFO - Starting attempt 1 of 1
[2025-06-15T16:50:45.136+0000] {taskinstance.py:2330} INFO - Executing <Task(PythonOperator): load.transform_fact_sales> on 2025-06-15 16:50:05.830452+00:00
[2025-06-15T16:50:45.143+0000] {standard_task_runner.py:63} INFO - Started process 587 to run task
[2025-06-15T16:50:45.146+0000] {standard_task_runner.py:90} INFO - Running: ['***', 'tasks', 'run', 'globalsuperstore', 'load.transform_fact_sales', 'manual__2025-06-15T16:50:05.830452+00:00', '--job-id', '97', '--raw', '--subdir', 'DAGS_FOLDER/global_superstore_dw_etl.py', '--cfg-path', '/tmp/tmp8nzlcvnj']
[2025-06-15T16:50:45.148+0000] {standard_task_runner.py:91} INFO - Job 97: Subtask load.transform_fact_sales
[2025-06-15T16:50:45.149+0000] {cli_action_loggers.py:70} DEBUG - Calling callbacks: [<function default_action_log at 0x7fd327729750>]
[2025-06-15T16:50:45.195+0000] {taskinstance.py:1042} DEBUG - previous_execution_date was called
[2025-06-15T16:50:45.211+0000] {task_command.py:426} INFO - Running <TaskInstance: globalsuperstore.load.transform_fact_sales manual__2025-06-15T16:50:05.830452+00:00 [running]> on host a40e01b9e58f
[2025-06-15T16:50:45.212+0000] {settings.py:363} DEBUG - Disposing DB connection pool (PID 587)
[2025-06-15T16:50:45.213+0000] {settings.py:250} DEBUG - Setting up DB connection pool (PID 587)
[2025-06-15T16:50:45.213+0000] {settings.py:298} DEBUG - settings.prepare_engine_args(): Using NullPool
[2025-06-15T16:50:45.251+0000] {taskinstance.py:1042} DEBUG - previous_execution_date was called
[2025-06-15T16:50:45.258+0000] {taskinstance.py:1845} DEBUG - Clearing XCom data
[2025-06-15T16:50:45.269+0000] {retries.py:91} DEBUG - Running RenderedTaskInstanceFields.write with retries. Try 1 of 3
[2025-06-15T16:50:45.293+0000] {retries.py:91} DEBUG - Running RenderedTaskInstanceFields._do_delete_old_records with retries. Try 1 of 3
[2025-06-15T16:50:45.307+0000] {taskinstance.py:2648} INFO - Exporting env vars: AIRFLOW_CTX_DAG_OWNER='***' AIRFLOW_CTX_DAG_ID='globalsuperstore' AIRFLOW_CTX_TASK_ID='load.transform_fact_sales' AIRFLOW_CTX_EXECUTION_DATE='2025-06-15T16:50:05.830452+00:00' AIRFLOW_CTX_TRY_NUMBER='1' AIRFLOW_CTX_DAG_RUN_ID='manual__2025-06-15T16:50:05.830452+00:00'
[2025-06-15T16:50:45.308+0000] {__init__.py:115} DEBUG - Preparing lineage inlets and outlets
[2025-06-15T16:50:45.308+0000] {__init__.py:154} DEBUG - inlets: [], outlets: []
[2025-06-15T16:50:45.309+0000] {taskinstance.py:430} INFO - ::endgroup::
[2025-06-15T16:50:45.331+0000] {base.py:84} INFO - Using connection ID 'postgres' for task execution.
[2025-06-15T16:50:45.343+0000] {base.py:84} INFO - Using connection ID 'postgres' for task execution.
[2025-06-15T16:50:45.490+0000] {taskinstance.py:441} INFO - ::group::Post task execution logs
[2025-06-15T16:50:45.491+0000] {taskinstance.py:2905} ERROR - Task failed with exception
Traceback (most recent call last):
  File "/home/airflow/.local/lib/python3.10/site-packages/sqlalchemy/engine/base.py", line 1910, in _execute_context
    self.dialect.do_execute(
  File "/home/airflow/.local/lib/python3.10/site-packages/sqlalchemy/engine/default.py", line 736, in do_execute
    cursor.execute(statement, parameters)
psycopg2.errors.UndefinedColumn: column "customer_id" referenced in foreign key constraint does not exist


The above exception was the direct cause of the following exception:

Traceback (most recent call last):
  File "/home/airflow/.local/lib/python3.10/site-packages/airflow/models/taskinstance.py", line 465, in _execute_task
    result = _execute_callable(context=context, **execute_callable_kwargs)
  File "/home/airflow/.local/lib/python3.10/site-packages/airflow/models/taskinstance.py", line 432, in _execute_callable
    return execute_callable(context=context, **execute_callable_kwargs)
  File "/home/airflow/.local/lib/python3.10/site-packages/airflow/models/baseoperator.py", line 401, in wrapper
    return func(self, *args, **kwargs)
  File "/home/airflow/.local/lib/python3.10/site-packages/airflow/operators/python.py", line 235, in execute
    return_value = self.execute_callable()
  File "/home/airflow/.local/lib/python3.10/site-packages/airflow/operators/python.py", line 252, in execute_callable
    return self.python_callable(*self.op_args, **self.op_kwargs)
  File "/opt/airflow/dags/transform_fact_sales.py", line 9, in transform_fact_sales
    warehouse_operator.create_fact_sales_table(schema='warehouse')  # ⬅️ Dòng này rất quan trọng
  File "/opt/airflow/plugins/postgresql_operator.py", line 60, in create_fact_sales_table
    conn.execute(text(f'CREATE SCHEMA IF NOT EXISTS "{schema}"'))
  File "/home/airflow/.local/lib/python3.10/site-packages/sqlalchemy/engine/base.py", line 1385, in execute
    return meth(self, multiparams, params, _EMPTY_EXECUTION_OPTS)
  File "/home/airflow/.local/lib/python3.10/site-packages/sqlalchemy/sql/elements.py", line 334, in _execute_on_connection
    return connection._execute_clauseelement(
  File "/home/airflow/.local/lib/python3.10/site-packages/sqlalchemy/engine/base.py", line 1577, in _execute_clauseelement
    ret = self._execute_context(
  File "/home/airflow/.local/lib/python3.10/site-packages/sqlalchemy/engine/base.py", line 1953, in _execute_context
    self._handle_dbapi_exception(
  File "/home/airflow/.local/lib/python3.10/site-packages/sqlalchemy/engine/base.py", line 2134, in _handle_dbapi_exception
    util.raise_(
  File "/home/airflow/.local/lib/python3.10/site-packages/sqlalchemy/util/compat.py", line 211, in raise_
    raise exception
  File "/home/airflow/.local/lib/python3.10/site-packages/sqlalchemy/engine/base.py", line 1910, in _execute_context
    self.dialect.do_execute(
  File "/home/airflow/.local/lib/python3.10/site-packages/sqlalchemy/engine/default.py", line 736, in do_execute
    cursor.execute(statement, parameters)
sqlalchemy.exc.ProgrammingError: (psycopg2.errors.UndefinedColumn) column "customer_id" referenced in foreign key constraint does not exist

[SQL: 
        CREATE TABLE IF NOT EXISTS "warehouse".fact_sales (
            Order_ID VARCHAR NOT NULL,
            Order_Date DATE NOT NULL,
            Customer_ID VARCHAR NOT NULL,
            Product_ID VARCHAR NOT NULL,
            Location_ID INT NOT NULL,
            ShipMode_ID INT NOT NULL,
            Discount FLOAT,
            Profit FLOAT,
            Quantity INT,
            Sales FLOAT,
            PRIMARY KEY (Order_ID, Product_ID),
            FOREIGN KEY (Customer_ID) REFERENCES warehouse.dim_customer(Customer_ID),
            FOREIGN KEY (Product_ID) REFERENCES warehouse.dim_product(Product_ID),
            FOREIGN KEY (Location_ID) REFERENCES warehouse.dim_location(Location_ID),
            FOREIGN KEY (ShipMode_ID) REFERENCES warehouse.dim_shipmode(ShipMode_ID)
        );
        ]
(Background on this error at: https://sqlalche.me/e/14/f405)
[2025-06-15T16:50:45.565+0000] {taskinstance.py:562} DEBUG - Task Duration set to 0.460372
[2025-06-15T16:50:45.568+0000] {taskinstance.py:584} DEBUG - Clearing next_method and next_kwargs.
[2025-06-15T16:50:45.569+0000] {taskinstance.py:1206} INFO - Marking task as FAILED. dag_id=globalsuperstore, task_id=load.transform_fact_sales, run_id=manual__2025-06-15T16:50:05.830452+00:00, execution_date=20250615T165005, start_date=20250615T165045, end_date=20250615T165045
[2025-06-15T16:50:45.593+0000] {cli_action_loggers.py:88} DEBUG - Calling callbacks: []
[2025-06-15T16:50:45.594+0000] {standard_task_runner.py:110} ERROR - Failed to execute job 97 for task load.transform_fact_sales ((psycopg2.errors.UndefinedColumn) column "customer_id" referenced in foreign key constraint does not exist

[SQL: 
        CREATE TABLE IF NOT EXISTS "warehouse".fact_sales (
            Order_ID VARCHAR NOT NULL,
            Order_Date DATE NOT NULL,
            Customer_ID VARCHAR NOT NULL,
            Product_ID VARCHAR NOT NULL,
            Location_ID INT NOT NULL,
            ShipMode_ID INT NOT NULL,
            Discount FLOAT,
            Profit FLOAT,
            Quantity INT,
            Sales FLOAT,
            PRIMARY KEY (Order_ID, Product_ID),
            FOREIGN KEY (Customer_ID) REFERENCES warehouse.dim_customer(Customer_ID),
            FOREIGN KEY (Product_ID) REFERENCES warehouse.dim_product(Product_ID),
            FOREIGN KEY (Location_ID) REFERENCES warehouse.dim_location(Location_ID),
            FOREIGN KEY (ShipMode_ID) REFERENCES warehouse.dim_shipmode(ShipMode_ID)
        );
        ]
(Background on this error at: https://sqlalche.me/e/14/f405); 587)
[2025-06-15T16:50:45.640+0000] {local_task_job_runner.py:240} INFO - Task exited with return code 1
[2025-06-15T16:50:45.655+0000] {dagrun.py:931} DEBUG - number of tis tasks for <DagRun globalsuperstore @ 2025-06-15 16:50:05.830452+00:00: manual__2025-06-15T16:50:05.830452+00:00, state:running, queued_at: 2025-06-15 16:50:06.195501+00:00. externally triggered: True>: 0 task(s)
[2025-06-15T16:50:45.655+0000] {taskinstance.py:3503} INFO - 0 downstream tasks scheduled from follow-on schedule check
[2025-06-15T16:50:45.660+0000] {local_task_job_runner.py:222} INFO - ::endgroup::
