[2025-06-16T08:56:10.098+0000] {taskinstance.py:1042} DEBUG - previous_execution_date was called
[2025-06-16T08:56:10.134+0000] {__init__.py:54} DEBUG - Loading core task runner: StandardTaskRunner
[2025-06-16T08:56:10.148+0000] {taskinstance.py:1042} DEBUG - previous_execution_date was called
[2025-06-16T08:56:10.153+0000] {base_task_runner.py:73} DEBUG - Planning to run as the  user
[2025-06-16T08:56:10.175+0000] {local_task_job_runner.py:120} INFO - ::group::Pre task execution logs
[2025-06-16T08:56:10.244+0000] {taskinstance.py:2088} DEBUG - <TaskInstance: globalsuperstore.transform.transform_dim_locations manual__2025-06-16T08:55:40.571696+00:00 [queued]> dependency 'Previous Dagrun State' PASSED: True, The task did not have depends_on_past set.
[2025-06-16T08:56:10.245+0000] {taskinstance.py:2088} DEBUG - <TaskInstance: globalsuperstore.transform.transform_dim_locations manual__2025-06-16T08:55:40.571696+00:00 [queued]> dependency 'Not In Retry Period' PASSED: True, The task instance was not marked for retrying.
[2025-06-16T08:56:10.245+0000] {taskinstance.py:2088} DEBUG - <TaskInstance: globalsuperstore.transform.transform_dim_locations manual__2025-06-16T08:55:40.571696+00:00 [queued]> dependency 'Task Instance Not Running' PASSED: True, Task is not in running state.
[2025-06-16T08:56:10.255+0000] {taskinstance.py:2088} DEBUG - <TaskInstance: globalsuperstore.transform.transform_dim_locations manual__2025-06-16T08:55:40.571696+00:00 [queued]> dependency 'Task Instance State' PASSED: True, Task state queued was valid.
[2025-06-16T08:56:10.256+0000] {taskinstance.py:2076} INFO - Dependencies all met for dep_context=non-requeueable deps ti=<TaskInstance: globalsuperstore.transform.transform_dim_locations manual__2025-06-16T08:55:40.571696+00:00 [queued]>
[2025-06-16T08:56:10.257+0000] {taskinstance.py:2088} DEBUG - <TaskInstance: globalsuperstore.transform.transform_dim_locations manual__2025-06-16T08:55:40.571696+00:00 [queued]> dependency 'Previous Dagrun State' PASSED: True, The task did not have depends_on_past set.
[2025-06-16T08:56:10.265+0000] {taskinstance.py:2088} DEBUG - <TaskInstance: globalsuperstore.transform.transform_dim_locations manual__2025-06-16T08:55:40.571696+00:00 [queued]> dependency 'Pool Slots Available' PASSED: True, There are enough open slots in default_pool to execute the task
[2025-06-16T08:56:10.265+0000] {taskinstance.py:2088} DEBUG - <TaskInstance: globalsuperstore.transform.transform_dim_locations manual__2025-06-16T08:55:40.571696+00:00 [queued]> dependency 'Task Concurrency' PASSED: True, Task concurrency is not set.
[2025-06-16T08:56:10.266+0000] {taskinstance.py:2088} DEBUG - <TaskInstance: globalsuperstore.transform.transform_dim_locations manual__2025-06-16T08:55:40.571696+00:00 [queued]> dependency 'Not In Retry Period' PASSED: True, The task instance was not marked for retrying.
[2025-06-16T08:56:10.270+0000] {taskinstance.py:2076} INFO - Dependencies all met for dep_context=requeueable deps ti=<TaskInstance: globalsuperstore.transform.transform_dim_locations manual__2025-06-16T08:55:40.571696+00:00 [queued]>
[2025-06-16T08:56:10.271+0000] {taskinstance.py:2306} INFO - Starting attempt 1 of 1
[2025-06-16T08:56:10.287+0000] {taskinstance.py:2330} INFO - Executing <Task(PythonOperator): transform.transform_dim_locations> on 2025-06-16 08:55:40.571696+00:00
[2025-06-16T08:56:10.296+0000] {standard_task_runner.py:63} INFO - Started process 383 to run task
[2025-06-16T08:56:10.301+0000] {standard_task_runner.py:90} INFO - Running: ['***', 'tasks', 'run', 'globalsuperstore', 'transform.transform_dim_locations', 'manual__2025-06-16T08:55:40.571696+00:00', '--job-id', '165', '--raw', '--subdir', 'DAGS_FOLDER/global_superstore_dw_etl.py', '--cfg-path', '/tmp/tmpn2f2v1sv']
[2025-06-16T08:56:10.303+0000] {standard_task_runner.py:91} INFO - Job 165: Subtask transform.transform_dim_locations
[2025-06-16T08:56:10.304+0000] {cli_action_loggers.py:70} DEBUG - Calling callbacks: [<function default_action_log at 0x7f80ebb29750>]
[2025-06-16T08:56:10.363+0000] {taskinstance.py:1042} DEBUG - previous_execution_date was called
[2025-06-16T08:56:10.374+0000] {task_command.py:426} INFO - Running <TaskInstance: globalsuperstore.transform.transform_dim_locations manual__2025-06-16T08:55:40.571696+00:00 [running]> on host a40e01b9e58f
[2025-06-16T08:56:10.375+0000] {settings.py:363} DEBUG - Disposing DB connection pool (PID 383)
[2025-06-16T08:56:10.376+0000] {settings.py:250} DEBUG - Setting up DB connection pool (PID 383)
[2025-06-16T08:56:10.376+0000] {settings.py:298} DEBUG - settings.prepare_engine_args(): Using NullPool
[2025-06-16T08:56:10.459+0000] {taskinstance.py:1042} DEBUG - previous_execution_date was called
[2025-06-16T08:56:10.469+0000] {taskinstance.py:1845} DEBUG - Clearing XCom data
[2025-06-16T08:56:10.534+0000] {retries.py:91} DEBUG - Running RenderedTaskInstanceFields.write with retries. Try 1 of 3
[2025-06-16T08:56:10.564+0000] {retries.py:91} DEBUG - Running RenderedTaskInstanceFields._do_delete_old_records with retries. Try 1 of 3
[2025-06-16T08:56:10.592+0000] {taskinstance.py:2648} INFO - Exporting env vars: AIRFLOW_CTX_DAG_OWNER='***' AIRFLOW_CTX_DAG_ID='globalsuperstore' AIRFLOW_CTX_TASK_ID='transform.transform_dim_locations' AIRFLOW_CTX_EXECUTION_DATE='2025-06-16T08:55:40.571696+00:00' AIRFLOW_CTX_TRY_NUMBER='1' AIRFLOW_CTX_DAG_RUN_ID='manual__2025-06-16T08:55:40.571696+00:00'
[2025-06-16T08:56:10.594+0000] {__init__.py:115} DEBUG - Preparing lineage inlets and outlets
[2025-06-16T08:56:10.596+0000] {__init__.py:154} DEBUG - inlets: [], outlets: []
[2025-06-16T08:56:10.597+0000] {taskinstance.py:430} INFO - ::endgroup::
[2025-06-16T08:56:10.672+0000] {base.py:84} INFO - Using connection ID 'postgres' for task execution.
[2025-06-16T08:56:10.680+0000] {base.py:84} INFO - Using connection ID 'postgres' for task execution.
[2025-06-16T08:56:10.699+0000] {base.py:84} INFO - Using connection ID 'postgres' for task execution.
[2025-06-16T08:56:10.750+0000] {logging_mixin.py:188} WARNING - /home/***/.local/lib/python3.10/site-packages/***/providers/common/sql/hooks/sql.py:263 UserWarning: pandas only supports SQLAlchemy connectable (engine/connection) or database string URI or sqlite3 DBAPI2 connection. Other DBAPI2 objects are not tested. Please consider using SQLAlchemy.
[2025-06-16T08:56:11.030+0000] {taskinstance.py:441} INFO - ::group::Post task execution logs
[2025-06-16T08:56:11.031+0000] {taskinstance.py:2905} ERROR - Task failed with exception
Traceback (most recent call last):
  File "/home/airflow/.local/lib/python3.10/site-packages/sqlalchemy/engine/base.py", line 1910, in _execute_context
    self.dialect.do_execute(
  File "/home/airflow/.local/lib/python3.10/site-packages/sqlalchemy/engine/default.py", line 736, in do_execute
    cursor.execute(statement, parameters)
psycopg2.errors.DependentObjectsStillExist: cannot drop table warehouse.dim_location because other objects depend on it
DETAIL:  constraint fact_sales_location_id_fkey on table warehouse.fact_sales depends on table warehouse.dim_location
HINT:  Use DROP ... CASCADE to drop the dependent objects too.


The above exception was the direct cause of the following exception:

Traceback (most recent call last):
  File "/home/airflow/.local/lib/python3.10/site-packages/airflow/models/taskinstance.py", line 465, in _execute_task
    result = _execute_callable(context=context, **execute_callable_kwargs)
  File "/home/airflow/.local/lib/python3.10/site-packages/airflow/models/taskinstance.py", line 432, in _execute_callable
    return execute_callable(context=context, **execute_callable_kwargs)
  File "/home/airflow/.local/lib/python3.10/site-packages/airflow/models/baseoperator.py", line 401, in wrapper
    return func(self, *args, **kwargs)
  File "/home/airflow/.local/lib/python3.10/site-packages/airflow/operators/python.py", line 235, in execute
    return_value = self.execute_callable()
  File "/home/airflow/.local/lib/python3.10/site-packages/airflow/operators/python.py", line 252, in execute_callable
    return self.python_callable(*self.op_args, **self.op_kwargs)
  File "/opt/airflow/dags/transform_dim_locations.py", line 30, in transform_dim_locations
    warehouse_operator.save_data_to_postgres(
  File "/opt/airflow/plugins/postgresql_operator.py", line 22, in save_data_to_postgres
    schema: str = 'public',
  File "/home/airflow/.local/lib/python3.10/site-packages/pandas/core/generic.py", line 2987, in to_sql
    return sql.to_sql(
  File "/home/airflow/.local/lib/python3.10/site-packages/pandas/io/sql.py", line 695, in to_sql
    return pandas_sql.to_sql(
  File "/home/airflow/.local/lib/python3.10/site-packages/pandas/io/sql.py", line 1728, in to_sql
    table = self.prep_table(
  File "/home/airflow/.local/lib/python3.10/site-packages/pandas/io/sql.py", line 1631, in prep_table
    table.create()
  File "/home/airflow/.local/lib/python3.10/site-packages/pandas/io/sql.py", line 831, in create
    self.pd_sql.drop_table(self.name, self.schema)
  File "/home/airflow/.local/lib/python3.10/site-packages/pandas/io/sql.py", line 1782, in drop_table
    self.get_table(table_name, schema).drop(bind=self.connectable)
  File "/home/airflow/.local/lib/python3.10/site-packages/sqlalchemy/sql/schema.py", line 979, in drop
    bind._run_ddl_visitor(ddl.SchemaDropper, self, checkfirst=checkfirst)
  File "/home/airflow/.local/lib/python3.10/site-packages/sqlalchemy/engine/base.py", line 3238, in _run_ddl_visitor
    conn._run_ddl_visitor(visitorcallable, element, **kwargs)
  File "/home/airflow/.local/lib/python3.10/site-packages/sqlalchemy/engine/base.py", line 2221, in _run_ddl_visitor
    visitorcallable(self.dialect, self, **kwargs).traverse_single(element)
  File "/home/airflow/.local/lib/python3.10/site-packages/sqlalchemy/sql/visitors.py", line 524, in traverse_single
    return meth(obj, **kw)
  File "/home/airflow/.local/lib/python3.10/site-packages/sqlalchemy/sql/ddl.py", line 1106, in visit_table
    self.connection.execute(DropTable(table))
  File "/home/airflow/.local/lib/python3.10/site-packages/sqlalchemy/engine/base.py", line 1385, in execute
    return meth(self, multiparams, params, _EMPTY_EXECUTION_OPTS)
  File "/home/airflow/.local/lib/python3.10/site-packages/sqlalchemy/sql/ddl.py", line 80, in _execute_on_connection
    return connection._execute_ddl(
  File "/home/airflow/.local/lib/python3.10/site-packages/sqlalchemy/engine/base.py", line 1477, in _execute_ddl
    ret = self._execute_context(
  File "/home/airflow/.local/lib/python3.10/site-packages/sqlalchemy/engine/base.py", line 1953, in _execute_context
    self._handle_dbapi_exception(
  File "/home/airflow/.local/lib/python3.10/site-packages/sqlalchemy/engine/base.py", line 2134, in _handle_dbapi_exception
    util.raise_(
  File "/home/airflow/.local/lib/python3.10/site-packages/sqlalchemy/util/compat.py", line 211, in raise_
    raise exception
  File "/home/airflow/.local/lib/python3.10/site-packages/sqlalchemy/engine/base.py", line 1910, in _execute_context
    self.dialect.do_execute(
  File "/home/airflow/.local/lib/python3.10/site-packages/sqlalchemy/engine/default.py", line 736, in do_execute
    cursor.execute(statement, parameters)
sqlalchemy.exc.InternalError: (psycopg2.errors.DependentObjectsStillExist) cannot drop table warehouse.dim_location because other objects depend on it
DETAIL:  constraint fact_sales_location_id_fkey on table warehouse.fact_sales depends on table warehouse.dim_location
HINT:  Use DROP ... CASCADE to drop the dependent objects too.

[SQL: 
DROP TABLE warehouse.dim_location]
(Background on this error at: https://sqlalche.me/e/14/2j85)
[2025-06-16T08:56:11.055+0000] {taskinstance.py:562} DEBUG - Task Duration set to 0.798122
[2025-06-16T08:56:11.057+0000] {taskinstance.py:584} DEBUG - Clearing next_method and next_kwargs.
[2025-06-16T08:56:11.057+0000] {taskinstance.py:1206} INFO - Marking task as FAILED. dag_id=globalsuperstore, task_id=transform.transform_dim_locations, run_id=manual__2025-06-16T08:55:40.571696+00:00, execution_date=20250616T085540, start_date=20250616T085610, end_date=20250616T085611
[2025-06-16T08:56:11.077+0000] {cli_action_loggers.py:88} DEBUG - Calling callbacks: []
[2025-06-16T08:56:11.078+0000] {standard_task_runner.py:110} ERROR - Failed to execute job 165 for task transform.transform_dim_locations ((psycopg2.errors.DependentObjectsStillExist) cannot drop table warehouse.dim_location because other objects depend on it
DETAIL:  constraint fact_sales_location_id_fkey on table warehouse.fact_sales depends on table warehouse.dim_location
HINT:  Use DROP ... CASCADE to drop the dependent objects too.

[SQL: 
DROP TABLE warehouse.dim_location]
(Background on this error at: https://sqlalche.me/e/14/2j85); 383)
[2025-06-16T08:56:11.138+0000] {local_task_job_runner.py:240} INFO - Task exited with return code 1
[2025-06-16T08:56:11.147+0000] {taskinstance.py:3461} DEBUG - Skip locked rows, rollback
[2025-06-16T08:56:11.149+0000] {local_task_job_runner.py:222} INFO - ::endgroup::
