[2025-06-13T16:57:11.254+0000] {local_task_job_runner.py:120} INFO - ::group::Pre task execution logs
[2025-06-13T16:57:11.404+0000] {taskinstance.py:2076} INFO - Dependencies all met for dep_context=non-requeueable deps ti=<TaskInstance: GlobalSuperStore_dw_etl.extract.extract_and_load_to_staging manual__2025-06-13T16:56:50.202806+00:00 [queued]>
[2025-06-13T16:57:11.414+0000] {taskinstance.py:2076} INFO - Dependencies all met for dep_context=requeueable deps ti=<TaskInstance: GlobalSuperStore_dw_etl.extract.extract_and_load_to_staging manual__2025-06-13T16:56:50.202806+00:00 [queued]>
[2025-06-13T16:57:11.415+0000] {taskinstance.py:2306} INFO - Starting attempt 1 of 1
[2025-06-13T16:57:11.436+0000] {taskinstance.py:2330} INFO - Executing <Task(PythonOperator): extract.extract_and_load_to_staging> on 2025-06-13 16:56:50.202806+00:00
[2025-06-13T16:57:11.448+0000] {standard_task_runner.py:63} INFO - Started process 307 to run task
[2025-06-13T16:57:11.454+0000] {standard_task_runner.py:90} INFO - Running: ['***', 'tasks', 'run', 'GlobalSuperStore_dw_etl', 'extract.extract_and_load_to_staging', 'manual__2025-06-13T16:56:50.202806+00:00', '--job-id', '4', '--raw', '--subdir', 'DAGS_FOLDER/globalSuperstore.py', '--cfg-path', '/tmp/tmp5by_fudl']
[2025-06-13T16:57:11.457+0000] {standard_task_runner.py:91} INFO - Job 4: Subtask extract.extract_and_load_to_staging
[2025-06-13T16:57:11.514+0000] {task_command.py:426} INFO - Running <TaskInstance: GlobalSuperStore_dw_etl.extract.extract_and_load_to_staging manual__2025-06-13T16:56:50.202806+00:00 [running]> on host ce8c7e7a2a87
[2025-06-13T16:57:11.640+0000] {taskinstance.py:2648} INFO - Exporting env vars: AIRFLOW_CTX_DAG_OWNER='***' AIRFLOW_CTX_DAG_ID='GlobalSuperStore_dw_etl' AIRFLOW_CTX_TASK_ID='extract.extract_and_load_to_staging' AIRFLOW_CTX_EXECUTION_DATE='2025-06-13T16:56:50.202806+00:00' AIRFLOW_CTX_TRY_NUMBER='1' AIRFLOW_CTX_DAG_RUN_ID='manual__2025-06-13T16:56:50.202806+00:00'
[2025-06-13T16:57:11.641+0000] {taskinstance.py:430} INFO - ::endgroup::
[2025-06-13T16:57:11.693+0000] {taskinstance.py:441} INFO - ::group::Post task execution logs
[2025-06-13T16:57:11.705+0000] {taskinstance.py:2905} ERROR - Task failed with exception
Traceback (most recent call last):
  File "/home/airflow/.local/lib/python3.10/site-packages/airflow/models/taskinstance.py", line 465, in _execute_task
    result = _execute_callable(context=context, **execute_callable_kwargs)
  File "/home/airflow/.local/lib/python3.10/site-packages/airflow/models/taskinstance.py", line 432, in _execute_callable
    return execute_callable(context=context, **execute_callable_kwargs)
  File "/home/airflow/.local/lib/python3.10/site-packages/airflow/models/baseoperator.py", line 401, in wrapper
    return func(self, *args, **kwargs)
  File "/home/airflow/.local/lib/python3.10/site-packages/airflow/operators/python.py", line 235, in execute
    return_value = self.execute_callable()
  File "/home/airflow/.local/lib/python3.10/site-packages/airflow/operators/python.py", line 252, in execute_callable
    return self.python_callable(*self.op_args, **self.op_kwargs)
  File "/opt/airflow/dags/extract_data.py", line 27, in extract_and_load_to_staging
    df = source_operator.get_data_to_pd(f"SELECT * FROM {table}")
  File "/opt/airflow/plugins/mysql_operator.py", line 14, in get_data_to_pd
    return self.mysqlhook.get_pandas_df(query)
  File "/home/airflow/.local/lib/python3.10/site-packages/airflow/providers/common/sql/hooks/sql.py", line 262, in get_pandas_df
    with closing(self.get_conn()) as conn:
  File "/home/airflow/.local/lib/python3.10/site-packages/airflow/providers/mysql/hooks/mysql.py", line 188, in get_conn
    conn = self.connection or self.get_connection(getattr(self, self.conn_name_attr))
  File "/home/airflow/.local/lib/python3.10/site-packages/airflow/hooks/base.py", line 83, in get_connection
    conn = Connection.get_connection_from_secrets(conn_id)
  File "/home/airflow/.local/lib/python3.10/site-packages/airflow/models/connection.py", line 519, in get_connection_from_secrets
    raise AirflowNotFoundException(f"The conn_id `{conn_id}` isn't defined")
airflow.exceptions.AirflowNotFoundException: The conn_id `mysql` isn't defined
[2025-06-13T16:57:11.722+0000] {taskinstance.py:1206} INFO - Marking task as FAILED. dag_id=GlobalSuperStore_dw_etl, task_id=extract.extract_and_load_to_staging, run_id=manual__2025-06-13T16:56:50.202806+00:00, execution_date=20250613T165650, start_date=20250613T165711, end_date=20250613T165711
[2025-06-13T16:57:11.737+0000] {standard_task_runner.py:110} ERROR - Failed to execute job 4 for task extract.extract_and_load_to_staging (The conn_id `mysql` isn't defined; 307)
[2025-06-13T16:57:11.790+0000] {local_task_job_runner.py:240} INFO - Task exited with return code 1
[2025-06-13T16:57:11.811+0000] {taskinstance.py:3503} INFO - 0 downstream tasks scheduled from follow-on schedule check
[2025-06-13T16:57:11.814+0000] {local_task_job_runner.py:222} INFO - ::endgroup::
